Workbook

Sheet PRINCIPAL
D2: CALZADO - Resumen Enero / Junio 2026
C4: TOTAL | E4: TOTAL
C5: Pares | E5: Fact ($)
N6: Simulador
B7: =AUX!G3 -> ENERO | C7: =+'ENE 26'!AM9 -> 302 | E7: =+'ENE 26'!AO9 -> 10926096 | G7: MIX CALZADO | L7: COMPRA | M7: COMPRA | N7: COMPRA
B8: =AUX!G4 -> FEBRERO | C8: =+'FEB 26'!AM9 -> 264 | E8: =+'FEB 26'!AO9 -> 9563422.5 | G8: Género | H8: Categoría | I8: Share Mix Vol | J8: Desvío | L8: % | M8: UN | N8: UN | AC8: CASUAL | AD8: RUN/TRA | AE8: MULTI | AF8: KIDS
B9: =AUX!G5 -> MARZO | C9: =+'MAR 26'!AM9 -> 396 | E9: =+'MAR 26'!AO9 -> 15972406 | G9: Adulto | H9: Running/Training | I9: 0.22 | J9: +/- 3% | L9: =+AD15/$C$13 -> 0 | M9: =+AD15 -> 0 | N9: =+$N$13*I9 -> 660 | AB9: ENERO | AC9: =+'ENE 26'!$XEO$12 -> 64 | AD9: =+'ENE 26'!$XEP$12 -> 0 | AE9: =+'ENE 26'!$XEQ$12 -> 0 | AF9: =+'ENE 26'!$XER$12 -> 66
B10: =AUX!G6 -> ABRIL | C10: =+'ABR 26'!AM9 -> 416 | E10: =+'ABR 26'!AO9 -> 14869305 | G10: Adulto | H10: Casual | I10: 0.25 | J10: +/- 3% | L10: =+AC15/$C$13 -> 0.24842484 | M10: =+AC15 -> 552 | N10: =+$N$13*I10 -> 750 | AB10: FEBRERO | AC10: =+'FEB 26'!$XEO$12 -> 12 | AD10: =+'FEB 26'!$XEP$12 -> 0 | AE10: =+'FEB 26'!$XEQ$12 -> 0 | AF10: =+'FEB 26'!$XER$12 -> 142
B11: =AUX!G7 -> MAYO | C11: =+'MAY 26'!AM9 -> 392 | E11: =+'MAY 26'!AO9 -> 15989519 | G11: Adulto | H11: *Multideporte | I11: 0.28 | J11: +/- 3% | L11: =+AE15/$C$13 -> 0 | M11: =+AE15 -> 0 | N11: =+$N$13*I11 -> 840 | AB11: MARZO | AC11: =+'MAR 26'!$XEP$12 -> 182 | AD11: =+'MAR 26'!$XEQ$12 -> 0 | AE11: =+'MAR 26'!$XER$12 -> 0 | AF11: =+'MAR 26'!$XES$12 -> 56
B12: =AUX!G8 -> JUNIO | C12: =+'JUN 26'!AM9 -> 452 | E12: =+'JUN 26'!AO9 -> 18638930 | G12: Kids | H12: Kids | I12: 0.25 | J12: +/- 3% | L12: =+AF15/$C$13 -> 0.2070207 | M12: =+AF15 -> 460 | N12: =+$N$13*I12 -> 750 | AB12: ABRIL | AC12: =+'ABR 26'!$XEP$12 -> 74 | AD12: =+'ABR 26'!$XEQ$12 -> 0 | AE12: =+'ABR 26'!$XER$12 -> 0 | AF12: =+'ABR 26'!$XES$12 -> 130
B13: TOTAL | C13: =+SUM(C7:C12) -> 2222 | E13: =+SUM(E7:E12) -> 85959679 | G13: *Incluye Fútbol (10%), Tenis (11%), Outdoor(4%), Basquet (3%) | M13: =+SUM(M9:M12) -> 1012 | N13: 3000 | AB13: MAYO | AC13: =+'MAY 26'!$XEP$12 -> 66 | AD13: =+'MAY 26'!$XEQ$12 -> 0 | AE13: =+'MAY 26'!$XER$12 -> 0 | AF13: =+'MAY 26'!$XES$12 -> 46
AB14: JUNIO | AC14: =+'JUN 26'!$XEP$12 -> 154 | AD14: =+'JUN 26'!$XEQ$12 -> 0 | AE14: =+'JUN 26'!$XER$12 -> 0 | AF14: =+'JUN 26'!$XES$12 -> 20
L15: Poner unidades a comprar | AB15: TOTAL | AC15: =+SUM(AC9:AC14) -> 552 | AD15: =+SUM(AD9:AD14) -> 0 | AE15: =+SUM(AE9:AE14) -> 0 | AF15: =+SUM(AF9:AF14) -> 460

Sheet RESUMEN CATEGORIAS
D2: =PRINCIPAL!D2 -> CALZADO - Resumen Enero / Junio 2026
C4: TOTAL | E4: TOTAL | G4: CATEGORIA | J4: Pared | K4: Var | M4: GENERO | Q4: Pared | R4: Var | AD4: 60 | AQ4: CUARTOS
C5: Pares | E5: Fact ($) | G5: Pares | J5: Ideal | K5: pp | M5: Pares | Q5: Ideal | R5: pp | AD5: 120 | AH5: Categoría | AI5: Total | AK5: Categoría | AL5: Total | AQ5: Pares
B7: =AUX!G3 -> ENERO | C7: =+'ENE 26'!AM9 -> 302 | E7: =+'ENE 26'!AO9 -> 10926096 | G7: CASUAL | H7: =+SUMIF('ENE 26'!$AP:$AP,G7,'ENE 26'!$AM:$AM)+SUMIF('FEB 26'!$AP:$AP,G7,'FEB 26'!$AM:$AM)+SUMIF('MAR 26'!$AP:$AP,G7,'MAR 26'!$AM:$AM)+SUMIF('ABR 26'!$AP:$AP,G7,'ABR 26'!$AM:$AM)+SUMIF('MAY 26'!$AP:$AP,G7,'MAY 26'!$AM:$AM)+SUMIF('JUN 26'!$AP:$AP,G7,'JUN 26'!$AM:$AM) -> 718 | I7: =+IFERROR(H7/$H$14,"-") -> 0.32313231 | J7: =+IFERROR(IF($E$19=60,VLOOKUP(G7,$AK$7:$AM$14,3,0),IF($E$19=120,VLOOKUP(G7,$AH$7:$AJ$15,3,0),0)),0) -> 0 | K7: =+IFERROR((I7-J7)*100,"-") -> 32.313231 | M7: HOMBRE | N7: =+SUMIF('ENE 26'!$A:$A,M7,'ENE 26'!$AM:$AM)+SUMIF('FEB 26'!$A:$A,M7,'FEB 26'!$AM:$AM)+SUMIF('MAR 26'!$A:$A,M7,'MAR 26'!$AM:$AM)+SUMIF('ABR 26'!$A:$A,M7,'ABR 26'!$AM:$AM)+SUMIF('MAY 26'!$A:$A,M7,'MAY 26'!$AM:$AM)+SUMIF('JUN 26'!$A:$A,M7,'JUN 26'!$AM:$AM) -> 730 | O7: =+IFERROR(N7/$N$12,"-") -> 0.32853285 | P7: Hombre | Q7: =+IFERROR(IF($E$19=60,VLOOKUP(M7,$AK$22:$AM$26,3,0),IF($E$19=120,VLOOKUP(M7,$AH$22:$AJ$26,3,0),0)),0) -> 0 | R7: =+IFERROR((O7-Q7)*100,"-") -> 32.853285 | AD7: 0.5 | AE7: =+CONCATENATE("Menor que ",AD7," = ROJO") -> Menor que 0,5 = ROJO | AH7: CASUAL | AI7: =+COUNTIF(#REF!,AH7) -> #REF! | AJ7: =+AI7/$AI$14 -> #REF! | AK7: CASUAL | AL7: =+COUNTIF(#REF!,AK7) -> #REF! | AM7: =+AL7/$AL$14 -> #REF! | AN7: Running Retro | AO7: CASUAL | AQ7: CASUAL | AR7: 250 | AS7: =+IFERROR(AR7/$AR$11,"-") -> 0.25
B8: =AUX!G4 -> FEBRERO | C8: =+'FEB 26'!AM9 -> 264 | E8: =+'FEB 26'!AO9 -> 9563422.5 | G8: RUNNING | H8: =+SUMIF('ENE 26'!$AP:$AP,G8,'ENE 26'!$AM:$AM)+SUMIF('FEB 26'!$AP:$AP,G8,'FEB 26'!$AM:$AM)+SUMIF('MAR 26'!$AP:$AP,G8,'MAR 26'!$AM:$AM)+SUMIF('ABR 26'!$AP:$AP,G8,'ABR 26'!$AM:$AM)+SUMIF('MAY 26'!$AP:$AP,G8,'MAY 26'!$AM:$AM)+SUMIF('JUN 26'!$AP:$AP,G8,'JUN 26'!$AM:$AM) -> 576 | I8: =+IFERROR(H8/$H$14,"-") -> 0.25922592 | J8: =+IFERROR(IF($E$19=60,VLOOKUP(G8,$AK$7:$AM$14,3,0),IF($E$19=120,VLOOKUP(G8,$AH$7:$AJ$15,3,0),0)),0) -> 0 | K8: =+IFERROR((I8-J8)*100,"-") -> 25.922592 | M8: MUJER | N8: =+SUMIF('ENE 26'!$A:$A,M8,'ENE 26'!$AM:$AM)+SUMIF('FEB 26'!$A:$A,M8,'FEB 26'!$AM:$AM)+SUMIF('MAR 26'!$A:$A,M8,'MAR 26'!$AM:$AM)+SUMIF('ABR 26'!$A:$A,M8,'ABR 26'!$AM:$AM)+SUMIF('MAY 26'!$A:$A,M8,'MAY 26'!$AM:$AM)+SUMIF('JUN 26'!$A:$A,M8,'JUN 26'!$AM:$AM) -> 482 | O8: =+IFERROR(N8/$N$12,"-") -> 0.21692169 | P8: Mujer | Q8: =+IFERROR(IF($E$19=60,VLOOKUP(M8,$AK$22:$AM$26,3,0),IF($E$19=120,VLOOKUP(M8,$AH$22:$AJ$26,3,0),0)),0) -> 0 | R8: =+IFERROR((O8-Q8)*100,"-") -> 21.692169 | AD8: 0.75 | AE8: =+CONCATENATE("Entre ",AD7," y ",AD8," = AMARILLO") -> Entre 0,5 y 0,75 = AMARILLO | AH8: RUNNING | AI8: =+COUNTIF(#REF!,AH8) -> #REF! | AJ8: =+AI8/$AI$14 -> #REF! | AK8: RUNNING | AL8: =+COUNTIF(#REF!,AK8) -> #REF! | AM8: =+AL8/$AL$14 -> #REF! | AN8: Tenis Retro | AO8: CASUAL | AQ8: RUNNING+TRAINING | AR8: 250 | AS8: =+IFERROR(AR8/$AR$11,"-") -> 0.25
B9: =AUX!G5 -> MARZO | C9: =+'MAR 26'!AM9 -> 396 | E9: =+'MAR 26'!AO9 -> 15972406 | G9: TENIS | H9: =+SUMIF('ENE 26'!$AP:$AP,G9,'ENE 26'!$AM:$AM)+SUMIF('FEB 26'!$AP:$AP,G9,'FEB 26'!$AM:$AM)+SUMIF('MAR 26'!$AP:$AP,G9,'MAR 26'!$AM:$AM)+SUMIF('ABR 26'!$AP:$AP,G9,'ABR 26'!$AM:$AM)+SUMIF('MAY 26'!$AP:$AP,G9,'MAY 26'!$AM:$AM)+SUMIF('JUN 26'!$AP:$AP,G9,'JUN 26'!$AM:$AM) -> 0 | I9: =+IFERROR(H9/$H$14,"-") -> 0 | J9: =+IFERROR(IF($E$19=60,VLOOKUP(G9,$AK$7:$AM$14,3,0),IF($E$19=120,VLOOKUP(G9,$AH$7:$AJ$15,3,0),0)),0) -> 0 | K9: =+IFERROR((I9-J9)*100,"-") -> 0 | M9: UNISEX | N9: =+SUMIF('ENE 26'!$A:$A,M9,'ENE 26'!$AM:$AM)+SUMIF('FEB 26'!$A:$A,M9,'FEB 26'!$AM:$AM)+SUMIF('MAR 26'!$A:$A,M9,'MAR 26'!$AM:$AM)+SUMIF('ABR 26'!$A:$A,M9,'ABR 26'!$AM:$AM)+SUMIF('MAY 26'!$A:$A,M9,'MAY 26'!$AM:$AM)+SUMIF('JUN 26'!$A:$A,M9,'JUN 26'!$AM:$AM) -> 470 | O9: =+IFERROR(N9/$N$12,"-") -> 0.21152115 | P9: Unisex | Q9: =+IFERROR(IF($E$19=60,VLOOKUP(M9,$AK$22:$AM$26,3,0),IF($E$19=120,VLOOKUP(M9,$AH$22:$AJ$26,3,0),0)),0) -> 0 | R9: =+IFERROR((O9-Q9)*100,"-") -> 21.152115 | AD9: 1 | AE9: =+CONCATENATE("Mayor que ",AD8," = VERDE") -> Mayor que 0,75 = VERDE | AH9: TENIS | AI9: =+COUNTIF(#REF!,AH9) -> #REF! | AJ9: =+AI9/$AI$14 -> #REF! | AK9: TENIS | AL9: =+COUNTIF(#REF!,AK9) -> #REF! | AM9: =+AL9/$AL$14 -> #REF! | AN9: Casual Deportivo | AO9: CASUAL | AQ9: MULTIDEPORTE | AR9: 250 | AS9: =+IFERROR(AR9/$AR$11,"-") -> 0.25
B10: =AUX!G6 -> ABRIL | C10: =+'ABR 26'!AM9 -> 416 | E10: =+'ABR 26'!AO9 -> 14869305 | G10: TRAINING | H10: =+SUMIF('ENE 26'!$AP:$AP,G10,'ENE 26'!$AM:$AM)+SUMIF('FEB 26'!$AP:$AP,G10,'FEB 26'!$AM:$AM)+SUMIF('MAR 26'!$AP:$AP,G10,'MAR 26'!$AM:$AM)+SUMIF('ABR 26'!$AP:$AP,G10,'ABR 26'!$AM:$AM)+SUMIF('MAY 26'!$AP:$AP,G10,'MAY 26'!$AM:$AM)+SUMIF('JUN 26'!$AP:$AP,G10,'JUN 26'!$AM:$AM) -> 422 | I10: =+IFERROR(H10/$H$14,"-") -> 0.18991899 | J10: =+IFERROR(IF($E$19=60,VLOOKUP(G10,$AK$7:$AM$14,3,0),IF($E$19=120,VLOOKUP(G10,$AH$7:$AJ$15,3,0),0)),0) -> 0 | K10: =+IFERROR((I10-J10)*100,"-") -> 18.991899 | M10: KIDS | N10: =+SUMIF('ENE 26'!$A:$A,M10,'ENE 26'!$AM:$AM)+SUMIF('FEB 26'!$A:$A,M10,'FEB 26'!$AM:$AM)+SUMIF('MAR 26'!$A:$A,M10,'MAR 26'!$AM:$AM)+SUMIF('ABR 26'!$A:$A,M10,'ABR 26'!$AM:$AM)+SUMIF('MAY 26'!$A:$A,M10,'MAY 26'!$AM:$AM)+SUMIF('JUN 26'!$A:$A,M10,'JUN 26'!$AM:$AM) -> 540 | O10: =+IFERROR(N10/$N$12,"-") -> 0.2430243 | P10: Kids | Q10: =+IFERROR(IF($E$19=60,VLOOKUP(M10,$AK$22:$AM$26,3,0),IF($E$19=120,VLOOKUP(M10,$AH$22:$AJ$26,3,0),0)),0) -> 0 | R10: =+IFERROR((O10-Q10)*100,"-") -> 24.30243 | AH10: TRAINING | AI10: =+COUNTIF(#REF!,AH10) -> #REF! | AJ10: =+AI10/$AI$14 -> #REF! | AK10: TRAINING | AL10: =+COUNTIF(#REF!,AK10) -> #REF! | AM10: =+AL10/$AL$14 -> #REF! | AN10: Ugly | AO10: CASUAL | AQ10: KIDS | AR10: 250 | AS10: =+IFERROR(AR10/$AR$11,"-") -> 0.25
B11: =AUX!G7 -> MAYO | C11: =+'MAY 26'!AM9 -> 392 | E11: =+'MAY 26'!AO9 -> 15989519 | G11: FUTBOL | H11: =+SUMIF('ENE 26'!$AP:$AP,G11,'ENE 26'!$AM:$AM)+SUMIF('FEB 26'!$AP:$AP,G11,'FEB 26'!$AM:$AM)+SUMIF('MAR 26'!$AP:$AP,G11,'MAR 26'!$AM:$AM)+SUMIF('ABR 26'!$AP:$AP,G11,'ABR 26'!$AM:$AM)+SUMIF('MAY 26'!$AP:$AP,G11,'MAY 26'!$AM:$AM)+SUMIF('JUN 26'!$AP:$AP,G11,'JUN 26'!$AM:$AM) -> 92 | I11: =+IFERROR(H11/$H$14,"-") -> 0.04140414 | J11: =+IFERROR(IF($E$19=60,VLOOKUP(G11,$AK$7:$AM$14,3,0),IF($E$19=120,VLOOKUP(G11,$AH$7:$AJ$15,3,0),0)),0) -> 0 | K11: =+IFERROR((I11-J11)*100,"-") -> 4.140414 | M11: BEBE | N11: =+SUMIF('ENE 26'!$A:$A,M11,'ENE 26'!$AM:$AM)+SUMIF('FEB 26'!$A:$A,M11,'FEB 26'!$AM:$AM)+SUMIF('MAR 26'!$A:$A,M11,'MAR 26'!$AM:$AM)+SUMIF('ABR 26'!$A:$A,M11,'ABR 26'!$AM:$AM)+SUMIF('MAY 26'!$A:$A,M11,'MAY 26'!$AM:$AM)+SUMIF('JUN 26'!$A:$A,M11,'JUN 26'!$AM:$AM) -> 0 | O11: =+IFERROR(N11/$N$12,"-") -> 0 | P11: Bebe | Q11: =+IFERROR(IF($E$19=60,VLOOKUP(M11,$AK$22:$AM$26,3,0),IF($E$19=120,VLOOKUP(M11,$AH$22:$AJ$26,3,0),0)),0) -> 0 | R11: =+IFERROR((O11-Q11)*100,"-") -> 0 | AH11: FUTBOL | AI11: =+COUNTIF(#REF!,AH11) -> #REF! | AJ11: =+AI11/$AI$14 -> #REF! | AK11: FUTBOL | AL11: =+COUNTIF(#REF!,AK11) -> #REF! | AM11: =+AL11/$AL$14 -> #REF! | AN11: AV | AO11: CASUAL | AQ11: TOTAL | AR11: =+SUM(AR7:AR10) -> 1000 | AS11: =+SUM(AS7:AS10) -> 1
B12: =AUX!G8 -> JUNIO | C12: =+'JUN 26'!AM9 -> 452 | E12: =+'JUN 26'!AO9 -> 18638930 | G12: OUTDOOR | H12: =+SUMIF('ENE 26'!$AP:$AP,G12,'ENE 26'!$AM:$AM)+SUMIF('FEB 26'!$AP:$AP,G12,'FEB 26'!$AM:$AM)+SUMIF('MAR 26'!$AP:$AP,G12,'MAR 26'!$AM:$AM)+SUMIF('ABR 26'!$AP:$AP,G12,'ABR 26'!$AM:$AM)+SUMIF('MAY 26'!$AP:$AP,G12,'MAY 26'!$AM:$AM)+SUMIF('JUN 26'!$AP:$AP,G12,'JUN 26'!$AM:$AM) -> 398 | I12: =+IFERROR(H12/$H$14,"-") -> 0.17911791 | J12: =+IFERROR(IF($E$19=60,VLOOKUP(G12,$AK$7:$AM$14,3,0),IF($E$19=120,VLOOKUP(G12,$AH$7:$AJ$15,3,0),0)),0) -> 0 | K12: =+IFERROR((I12-J12)*100,"-") -> 17.911791 | M12: TOTAL | N12: =+SUM(N7:N11) -> 2222 | O12: =+SUM(O7:O11) -> 1 | AH12: OUTDOOR | AI12: =+COUNTIF(#REF!,AH12) -> #REF! | AJ12: =+AI12/$AI$14 -> #REF! | AK12: OUTDOOR | AL12: =+COUNTIF(#REF!,AK12) -> #REF! | AM12: =+AL12/$AL$14 -> #REF! | AN12: AV - Clásicos | AO12: CASUAL
B13: TOTAL | C13: =+SUM(C7:C12) -> 2222 | E13: =+SUM(E7:E12) -> 85959679 | G13: BASKET | H13: =+SUMIF('ENE 26'!$AP:$AP,G13,'ENE 26'!$AM:$AM)+SUMIF('FEB 26'!$AP:$AP,G13,'FEB 26'!$AM:$AM)+SUMIF('MAR 26'!$AP:$AP,G13,'MAR 26'!$AM:$AM)+SUMIF('ABR 26'!$AP:$AP,G13,'ABR 26'!$AM:$AM)+SUMIF('MAY 26'!$AP:$AP,G13,'MAY 26'!$AM:$AM)+SUMIF('JUN 26'!$AP:$AP,G13,'JUN 26'!$AM:$AM) -> 16 | I13: =+IFERROR(H13/$H$14,"-") -> 0.0072007201 | J13: =+IFERROR(IF($E$19=60,VLOOKUP(G13,$AK$7:$AM$14,3,0),IF($E$19=120,VLOOKUP(G13,$AH$7:$AJ$15,3,0),0)),0) -> 0 | K13: =+IFERROR((I13-J13)*100,"-") -> 0.72007201 | AH13: BASKET | AI13: =+COUNTIF(#REF!,AH13) -> #REF! | AJ13: =+AI13/$AI$14 -> #REF! | AK13: BASKET | AL13: =+COUNTIF(#REF!,AK13) -> #REF! | AM13: =+AL13/$AL$14 -> #REF! | AN13: Performance | AO13: RUNNING
G14: TOTAL | H14: =+SUM(H7:H13) -> 2222 | I14: =+SUM(I7:I13) -> 1 | AD14: -2 | AH14: Total general | AI14: =+SUM(AI7:AI13) -> #REF! | AJ14: =+AI14/$AI$14 -> #REF! | AK14: Total general | AL14: =+SUM(AL6:AL13) -> #REF! | AM14: =+AL14/$AL$14 -> #REF! | AN14: Training | AO14: TRAINING
AD15: 2 | AN15: Action | AO15: TENIS
AN16: Off Court | AO16: TENIS
AN17: Silos | AO17: FUTBOL
G18: CATEGORIA | J18: Pared | K18: Var | M18: GENERO | Q18: Pared | R18: Var | AN18: F4F | AO18: FUTBOL | AQ18: CUARTOS | AT18: FOCO
G19: Cant Art | J19: Ideal | K19: pp | M19: Cant Art | Q19: Ideal | R19: pp | AN19: Outdoor | AO19: OUTDOOR | AQ19: Cant Art | AT19: Cant Art
AN20: Basket | AO20: BASKET
G21: CASUAL | H21: =+COUNTIFS('ENE 26'!$AP:$AP,G21,'ENE 26'!$AM:$AM,">0")+COUNTIFS('FEB 26'!$AP:$AP,G21,'FEB 26'!$AM:$AM,">0")+COUNTIFS('MAR 26'!$AP:$AP,G21,'MAR 26'!$AM:$AM,">0")+COUNTIFS('ABR 26'!$AP:$AP,G21,'ABR 26'!$AM:$AM,">0")+COUNTIFS('MAY 26'!$AP:$AP,G21,'MAY 26'!$AM:$AM,">0")+COUNTIFS('JUN 26'!$AP:$AP,G21,'JUN 26'!$AM:$AM,">0") -> 26 | I21: =+IFERROR(H21/$H$28,"-") -> 0.27956989 | J21: =+IFERROR(IF($E$19=60,VLOOKUP(G21,$AK$7:$AM$14,3,0),IF($E$19=120,VLOOKUP(G21,$AH$7:$AJ$15,3,0),0)),0) -> 0 | K21: =+IFERROR((I21-J21)*100,"-") -> 27.956989 | M21: HOMBRE | N21: =+COUNTIFS('ENE 26'!$A:$A,M21,'ENE 26'!$AM:$AM,">0")+COUNTIFS('FEB 26'!$A:$A,M21,'FEB 26'!$AM:$AM,">0")+COUNTIFS('MAR 26'!$A:$A,M21,'MAR 26'!$AM:$AM,">0")+COUNTIFS('ABR 26'!$A:$A,M21,'ABR 26'!$AM:$AM,">0")+COUNTIFS('MAY 26'!$A:$A,M21,'MAY 26'!$AM:$AM,">0")+COUNTIFS('JUN 26'!$A:$A,M21,'JUN 26'!$AM:$AM,">0") -> 32 | O21: =+IFERROR(N21/$N$26,"-") -> 0.34408602 | P21: Hombre | Q21: =+IFERROR(IF($E$19=60,VLOOKUP(M21,$AK$22:$AM$26,3,0),IF($E$19=120,VLOOKUP(M21,$AH$22:$AJ$26,3,0),0)),0) -> 0 | R21: =+IFERROR((O21-Q21)*100,"-") -> 34.408602 | U21: CANT. MODELOS FOCO | V21: =SUM(AD25:AD32) -> 0 | AH21: Género | AI21: Total | AK21: Género | AL21: Total | AN21: Running | AO21: RUNNING | AQ21: CASUAL | AR21: =+COUNTIFS('ENE 26'!$AQ:$AQ,AQ21,'ENE 26'!$AM:$AM,">0")+COUNTIFS('FEB 26'!$AQ:$AQ,AQ21,'FEB 26'!$AM:$AM,">0")+COUNTIFS('MAR 26'!$AQ:$AQ,AQ21,'MAR 26'!$AM:$AM,">0")+COUNTIFS('ABR 26'!$AQ:$AQ,AQ21,'ABR 26'!$AM:$AM,">0")+COUNTIFS('MAY 26'!$AQ:$AQ,AQ21,'MAY 26'!$AM:$AM,">0")+COUNTIFS('JUN 26'!$AQ:$AQ,AQ21,'JUN 26'!$AM:$AM,">0") -> 21 | AS21: =+IFERROR(AR21/$AR$25,"-") -> 0.22580645 | AT21: =COUNTIFS($C$33:$C$59,AQ21,$F$33:$F$59,">0") -> 1
G22: RUNNING | H22: =+COUNTIFS('ENE 26'!$AP:$AP,G22,'ENE 26'!$AM:$AM,">0")+COUNTIFS('FEB 26'!$AP:$AP,G22,'FEB 26'!$AM:$AM,">0")+COUNTIFS('MAR 26'!$AP:$AP,G22,'MAR 26'!$AM:$AM,">0")+COUNTIFS('ABR 26'!$AP:$AP,G22,'ABR 26'!$AM:$AM,">0")+COUNTIFS('MAY 26'!$AP:$AP,G22,'MAY 26'!$AM:$AM,">0")+COUNTIFS('JUN 26'!$AP:$AP,G22,'JUN 26'!$AM:$AM,">0") -> 26 | I22: =+IFERROR(H22/$H$28,"-") -> 0.27956989 | J22: =+IFERROR(IF($E$19=60,VLOOKUP(G22,$AK$7:$AM$14,3,0),IF($E$19=120,VLOOKUP(G22,$AH$7:$AJ$15,3,0),0)),0) -> 0 | K22: =+IFERROR((I22-J22)*100,"-") -> 27.956989 | M22: MUJER | N22: =+COUNTIFS('ENE 26'!$A:$A,M22,'ENE 26'!$AM:$AM,">0")+COUNTIFS('FEB 26'!$A:$A,M22,'FEB 26'!$AM:$AM,">0")+COUNTIFS('MAR 26'!$A:$A,M22,'MAR 26'!$AM:$AM,">0")+COUNTIFS('ABR 26'!$A:$A,M22,'ABR 26'!$AM:$AM,">0")+COUNTIFS('MAY 26'!$A:$A,M22,'MAY 26'!$AM:$AM,">0")+COUNTIFS('JUN 26'!$A:$A,M22,'JUN 26'!$AM:$AM,">0") -> 21 | O22: =+IFERROR(N22/$N$26,"-") -> 0.22580645 | P22: Mujer | Q22: =+IFERROR(IF($E$19=60,VLOOKUP(M22,$AK$22:$AM$26,3,0),IF($E$19=120,VLOOKUP(M22,$AH$22:$AJ$26,3,0),0)),0) -> 0 | R22: =+IFERROR((O22-Q22)*100,"-") -> 22.580645 | AH22: BEBE | AI22: =+COUNTIF(#REF!,AH22) -> #REF! | AJ22: =+AI22/$AI$27 -> #REF! | AK22: BEBE | AL22: =+COUNTIF(#REF!,AK22) -> #REF! | AM22: =+AL22/$AL$27 -> #REF! | AQ22: RUNNING+TRAINING | AR22: =+COUNTIFS('ENE 26'!$AQ:$AQ,AQ22,'ENE 26'!$AM:$AM,">0")+COUNTIFS('FEB 26'!$AQ:$AQ,AQ22,'FEB 26'!$AM:$AM,">0")+COUNTIFS('MAR 26'!$AQ:$AQ,AQ22,'MAR 26'!$AM:$AM,">0")+COUNTIFS('ABR 26'!$AQ:$AQ,AQ22,'ABR 26'!$AM:$AM,">0")+COUNTIFS('MAY 26'!$AQ:$AQ,AQ22,'MAY 26'!$AM:$AM,">0")+COUNTIFS('JUN 26'!$AQ:$AQ,AQ22,'JUN 26'!$AM:$AM,">0") -> 32 | AS22: =+IFERROR(AR22/$AR$25,"-") -> 0.34408602 | AT22: =COUNTIFS($C$33:$C$59,AQ22,$F$33:$F$59,">0") -> 6
G23: TENIS | H23: =+COUNTIFS('ENE 26'!$AP:$AP,G23,'ENE 26'!$AM:$AM,">0")+COUNTIFS('FEB 26'!$AP:$AP,G23,'FEB 26'!$AM:$AM,">0")+COUNTIFS('MAR 26'!$AP:$AP,G23,'MAR 26'!$AM:$AM,">0")+COUNTIFS('ABR 26'!$AP:$AP,G23,'ABR 26'!$AM:$AM,">0")+COUNTIFS('MAY 26'!$AP:$AP,G23,'MAY 26'!$AM:$AM,">0")+COUNTIFS('JUN 26'!$AP:$AP,G23,'JUN 26'!$AM:$AM,">0") -> 0 | I23: =+IFERROR(H23/$H$28,"-") -> 0 | J23: =+IFERROR(IF($E$19=60,VLOOKUP(G23,$AK$7:$AM$14,3,0),IF($E$19=120,VLOOKUP(G23,$AH$7:$AJ$15,3,0),0)),0) -> 0 | K23: =+IFERROR((I23-J23)*100,"-") -> 0 | M23: UNISEX | N23: =+COUNTIFS('ENE 26'!$A:$A,M23,'ENE 26'!$AM:$AM,">0")+COUNTIFS('FEB 26'!$A:$A,M23,'FEB 26'!$AM:$AM,">0")+COUNTIFS('MAR 26'!$A:$A,M23,'MAR 26'!$AM:$AM,">0")+COUNTIFS('ABR 26'!$A:$A,M23,'ABR 26'!$AM:$AM,">0")+COUNTIFS('MAY 26'!$A:$A,M23,'MAY 26'!$AM:$AM,">0")+COUNTIFS('JUN 26'!$A:$A,M23,'JUN 26'!$AM:$AM,">0") -> 18 | O23: =+IFERROR(N23/$N$26,"-") -> 0.19354839 | P23: Unisex | Q23: =+IFERROR(IF($E$19=60,VLOOKUP(M23,$AK$22:$AM$26,3,0),IF($E$19=120,VLOOKUP(M23,$AH$22:$AJ$26,3,0),0)),0) -> 0 | R23: =+IFERROR((O23-Q23)*100,"-") -> 19.354839 | AH23: HOMBRE | AI23: =+COUNTIF(#REF!,AH23) -> #REF! | AJ23: =+AI23/$AI$27 -> #REF! | AK23: HOMBRE | AL23: =+COUNTIF(#REF!,AK23) -> #REF! | AM23: =+AL23/$AL$27 -> #REF! | AQ23: MULTIDEPORTE | AR23: =+COUNTIFS('ENE 26'!$AQ:$AQ,AQ23,'ENE 26'!$AM:$AM,">0")+COUNTIFS('FEB 26'!$AQ:$AQ,AQ23,'FEB 26'!$AM:$AM,">0")+COUNTIFS('MAR 26'!$AQ:$AQ,AQ23,'MAR 26'!$AM:$AM,">0")+COUNTIFS('ABR 26'!$AQ:$AQ,AQ23,'ABR 26'!$AM:$AM,">0")+COUNTIFS('MAY 26'!$AQ:$AQ,AQ23,'MAY 26'!$AM:$AM,">0")+COUNTIFS('JUN 26'!$AQ:$AQ,AQ23,'JUN 26'!$AM:$AM,">0") -> 18 | AS23: =+IFERROR(AR23/$AR$25,"-") -> 0.19354839 | AT23: =COUNTIFS($C$33:$C$59,AQ23,$F$33:$F$59,">0") -> 2
G24: TRAINING | H24: =+COUNTIFS('ENE 26'!$AP:$AP,G24,'ENE 26'!$AM:$AM,">0")+COUNTIFS('FEB 26'!$AP:$AP,G24,'FEB 26'!$AM:$AM,">0")+COUNTIFS('MAR 26'!$AP:$AP,G24,'MAR 26'!$AM:$AM,">0")+COUNTIFS('ABR 26'!$AP:$AP,G24,'ABR 26'!$AM:$AM,">0")+COUNTIFS('MAY 26'!$AP:$AP,G24,'MAY 26'!$AM:$AM,">0")+COUNTIFS('JUN 26'!$AP:$AP,G24,'JUN 26'!$AM:$AM,">0") -> 15 | I24: =+IFERROR(H24/$H$28,"-") -> 0.16129032 | J24: =+IFERROR(IF($E$19=60,VLOOKUP(G24,$AK$7:$AM$14,3,0),IF($E$19=120,VLOOKUP(G24,$AH$7:$AJ$15,3,0),0)),0) -> 0 | K24: =+IFERROR((I24-J24)*100,"-") -> 16.129032 | M24: KIDS | N24: =+COUNTIFS('ENE 26'!$A:$A,M24,'ENE 26'!$AM:$AM,">0")+COUNTIFS('FEB 26'!$A:$A,M24,'FEB 26'!$AM:$AM,">0")+COUNTIFS('MAR 26'!$A:$A,M24,'MAR 26'!$AM:$AM,">0")+COUNTIFS('ABR 26'!$A:$A,M24,'ABR 26'!$AM:$AM,">0")+COUNTIFS('MAY 26'!$A:$A,M24,'MAY 26'!$AM:$AM,">0")+COUNTIFS('JUN 26'!$A:$A,M24,'JUN 26'!$AM:$AM,">0") -> 22 | O24: =+IFERROR(N24/$N$26,"-") -> 0.23655914 | P24: Kids | Q24: =+IFERROR(IF($E$19=60,VLOOKUP(M24,$AK$22:$AM$26,3,0),IF($E$19=120,VLOOKUP(M24,$AH$22:$AJ$26,3,0),0)),0) -> 0 | R24: =+IFERROR((O24-Q24)*100,"-") -> 23.655914 | U24: MODELOS FOCO | V24: ENE | W24: FEB | X24: MAR | Y24: ABR | Z24: MAY | AA24: JUN | AB24: Compro | AC24: SI/NO | AD24: Modelos | AH24: KIDS | AI24: =+COUNTIF(#REF!,AH24) -> #REF! | AJ24: =+AI24/$AI$27 -> #REF! | AK24: KIDS | AL24: =+COUNTIF(#REF!,AK24) -> #REF! | AM24: =+AL24/$AL$27 -> #REF! | AQ24: KIDS | AR24: =+COUNTIFS('ENE 26'!$AQ:$AQ,AQ24,'ENE 26'!$AM:$AM,">0")+COUNTIFS('FEB 26'!$AQ:$AQ,AQ24,'FEB 26'!$AM:$AM,">0")+COUNTIFS('MAR 26'!$AQ:$AQ,AQ24,'MAR 26'!$AM:$AM,">0")+COUNTIFS('ABR 26'!$AQ:$AQ,AQ24,'ABR 26'!$AM:$AM,">0")+COUNTIFS('MAY 26'!$AQ:$AQ,AQ24,'MAY 26'!$AM:$AM,">0")+COUNTIFS('JUN 26'!$AQ:$AQ,AQ24,'JUN 26'!$AM:$AM,">0") -> 22 | AS24: =+IFERROR(AR24/$AR$25,"-") -> 0.23655914 | AT24: =COUNTIFS($C$33:$C$59,AQ24,$F$33:$F$59,">0") -> 3
G25: FUTBOL | H25: =+COUNTIFS('ENE 26'!$AP:$AP,G25,'ENE 26'!$AM:$AM,">0")+COUNTIFS('FEB 26'!$AP:$AP,G25,'FEB 26'!$AM:$AM,">0")+COUNTIFS('MAR 26'!$AP:$AP,G25,'MAR 26'!$AM:$AM,">0")+COUNTIFS('ABR 26'!$AP:$AP,G25,'ABR 26'!$AM:$AM,">0")+COUNTIFS('MAY 26'!$AP:$AP,G25,'MAY 26'!$AM:$AM,">0")+COUNTIFS('JUN 26'!$AP:$AP,G25,'JUN 26'!$AM:$AM,">0") -> 8 | I25: =+IFERROR(H25/$H$28,"-") -> 0.086021505 | J25: =+IFERROR(IF($E$19=60,VLOOKUP(G25,$AK$7:$AM$14,3,0),IF($E$19=120,VLOOKUP(G25,$AH$7:$AJ$15,3,0),0)),0) -> 0 | K25: =+IFERROR((I25-J25)*100,"-") -> 8.6021505 | M25: BEBE | N25: =+COUNTIFS('ENE 26'!$A:$A,M25,'ENE 26'!$AM:$AM,">0")+COUNTIFS('FEB 26'!$A:$A,M25,'FEB 26'!$AM:$AM,">0")+COUNTIFS('MAR 26'!$A:$A,M25,'MAR 26'!$AM:$AM,">0")+COUNTIFS('ABR 26'!$A:$A,M25,'ABR 26'!$AM:$AM,">0")+COUNTIFS('MAY 26'!$A:$A,M25,'MAY 26'!$AM:$AM,">0")+COUNTIFS('JUN 26'!$A:$A,M25,'JUN 26'!$AM:$AM,">0") -> 0 | O25: =+IFERROR(N25/$N$26,"-") -> 0 | P25: Bebe | Q25: =+IFERROR(IF($E$19=60,VLOOKUP(M25,$AK$22:$AM$26,3,0),IF($E$19=120,VLOOKUP(M25,$AH$22:$AJ$26,3,0),0)),0) -> 0 | R25: =+IFERROR((O25-Q25)*100,"-") -> 0 | T25: 1 | U25: T.350 MESH | V25: =VLOOKUP($U25,'ENE 26'!$C$14:$C$104,1,0) -> #N/A | W25: =VLOOKUP($U25,'FEB 26'!$C$14:$C$100,1,0) -> #N/A | X25: =VLOOKUP($U25,'MAR 26'!$C$14:$C$101,1,0) -> #N/A | Y25: =VLOOKUP($U25,'ABR 26'!$C$14:$C$101,1,0) -> #N/A | Z25: =VLOOKUP($U25,'MAY 26'!$C$14:$C$100,1,0) -> #N/A | AA25: =VLOOKUP($U25,'JUN 26'!$C$14:$C$103,1,0) -> #N/A | AB25: =COUNTIF(V25:AA25,U25) -> 0 | AC25: =IF(AB25>0,"SI","NO") -> NO | AD25: =IF(AC25="SI",1,0) -> 0 | AH25: MUJER | AI25: =+COUNTIF(#REF!,AH25) -> #REF! | AJ25: =+AI25/$AI$27 -> #REF! | AK25: MUJER | AL25: =+COUNTIF(#REF!,AK25) -> #REF! | AM25: =+AL25/$AL$27 -> #REF! | AQ25: TOTAL | AR25: =+SUM(AR21:AR24) -> 93 | AS25: =+SUM(AS21:AS24) -> 1
G26: OUTDOOR | H26: =+COUNTIFS('ENE 26'!$AP:$AP,G26,'ENE 26'!$AM:$AM,">0")+COUNTIFS('FEB 26'!$AP:$AP,G26,'FEB 26'!$AM:$AM,">0")+COUNTIFS('MAR 26'!$AP:$AP,G26,'MAR 26'!$AM:$AM,">0")+COUNTIFS('ABR 26'!$AP:$AP,G26,'ABR 26'!$AM:$AM,">0")+COUNTIFS('MAY 26'!$AP:$AP,G26,'MAY 26'!$AM:$AM,">0")+COUNTIFS('JUN 26'!$AP:$AP,G26,'JUN 26'!$AM:$AM,">0") -> 17 | I26: =+IFERROR(H26/$H$28,"-") -> 0.1827957 | J26: =+IFERROR(IF($E$19=60,VLOOKUP(G26,$AK$7:$AM$14,3,0),IF($E$19=120,VLOOKUP(G26,$AH$7:$AJ$15,3,0),0)),0) -> 0 | K26: =+IFERROR((I26-J26)*100,"-") -> 18.27957 | M26: TOTAL | N26: =+SUM(N21:N25) -> 93 | O26: =+SUM(O21:O25) -> 1 | T26: 2 | U26: MAMBA | V26: =VLOOKUP($U26,'ENE 26'!$C$14:$C$104,1,0) -> #N/A | W26: =VLOOKUP($U26,'FEB 26'!$C$14:$C$100,1,0) -> #N/A | X26: =VLOOKUP($U26,'MAR 26'!$C$14:$C$101,1,0) -> #N/A | Y26: =VLOOKUP($U26,'ABR 26'!$C$14:$C$101,1,0) -> #N/A | Z26: =VLOOKUP($U26,'MAY 26'!$C$14:$C$100,1,0) -> #N/A | AA26: =VLOOKUP($U26,'JUN 26'!$C$14:$C$103,1,0) -> #N/A | AB26: =COUNTIF(V26:AA26,U26) -> 0 | AC26: =IF(AB26>0,"SI","NO") -> NO | AD26: =IF(AC26="SI",1,0) -> 0 | AH26: UNISEX | AI26: =+COUNTIF(#REF!,AH26) -> #REF! | AJ26: =+AI26/$AI$27 -> #REF! | AK26: UNISEX | AL26: =+COUNTIF(#REF!,AK26) -> #REF! | AM26: =+AL26/$AL$27 -> #REF!
G27: BASKET | H27: =+COUNTIFS('ENE 26'!$AP:$AP,G27,'ENE 26'!$AM:$AM,">0")+COUNTIFS('FEB 26'!$AP:$AP,G27,'FEB 26'!$AM:$AM,">0")+COUNTIFS('MAR 26'!$AP:$AP,G27,'MAR 26'!$AM:$AM,">0")+COUNTIFS('ABR 26'!$AP:$AP,G27,'ABR 26'!$AM:$AM,">0")+COUNTIFS('MAY 26'!$AP:$AP,G27,'MAY 26'!$AM:$AM,">0")+COUNTIFS('JUN 26'!$AP:$AP,G27,'JUN 26'!$AM:$AM,">0") -> 1 | I27: =+IFERROR(H27/$H$28,"-") -> 0.010752688 | J27: =+IFERROR(IF($E$19=60,VLOOKUP(G27,$AK$7:$AM$14,3,0),IF($E$19=120,VLOOKUP(G27,$AH$7:$AJ$15,3,0),0)),0) -> 0 | K27: =+IFERROR((I27-J27)*100,"-") -> 1.0752688 | T27: 3 | U27: CHALPA | V27: =VLOOKUP($U27,'ENE 26'!$C$14:$C$104,1,0) -> #N/A | W27: =VLOOKUP($U27,'FEB 26'!$C$14:$C$100,1,0) -> #N/A | X27: =VLOOKUP($U27,'MAR 26'!$C$14:$C$101,1,0) -> #N/A | Y27: =VLOOKUP($U27,'ABR 26'!$C$14:$C$101,1,0) -> #N/A | Z27: =VLOOKUP($U27,'MAY 26'!$C$14:$C$100,1,0) -> #N/A | AA27: =VLOOKUP($U27,'JUN 26'!$C$14:$C$103,1,0) -> #N/A | AB27: =COUNTIF(V27:AA27,U27) -> 0 | AC27: =IF(AB27>0,"SI","NO") -> NO | AD27: =IF(AC27="SI",1,0) -> 0 | AH27: Total general | AI27: =+SUM(AI22:AI26) -> #REF! | AJ27: =+AI27/$AI$27 -> #REF! | AK27: Total general | AL27: =+SUM(AL22:AL26) -> #REF! | AM27: =+AL27/$AL$27 -> #REF!
G28: TOTAL | H28: =+SUM(H21:H27) -> 93 | I28: =+SUM(I21:I27) -> 1 | T28: 4 | U28: FAST | V28: =VLOOKUP($U28,'ENE 26'!$C$14:$C$104,1,0) -> #N/A | W28: =VLOOKUP($U28,'FEB 26'!$C$14:$C$100,1,0) -> #N/A | X28: =VLOOKUP($U28,'MAR 26'!$C$14:$C$101,1,0) -> #N/A | Y28: =VLOOKUP($U28,'ABR 26'!$C$14:$C$101,1,0) -> #N/A | Z28: =VLOOKUP($U28,'MAY 26'!$C$14:$C$100,1,0) -> #N/A | AA28: =VLOOKUP($U28,'JUN 26'!$C$14:$C$103,1,0) -> #N/A | AB28: =COUNTIF(V28:AA28,U28) -> 0 | AC28: =IF(AB28>0,"SI","NO") -> NO | AD28: =IF(AC28="SI",1,0) -> 0
T29: 5 | U29: SPLIT | V29: =VLOOKUP($U29,'ENE 26'!$C$14:$C$104,1,0) -> #N/A | W29: =VLOOKUP($U29,'FEB 26'!$C$14:$C$100,1,0) -> #N/A | X29: =VLOOKUP($U29,'MAR 26'!$C$14:$C$101,1,0) -> #N/A | Y29: =VLOOKUP($U29,'ABR 26'!$C$14:$C$101,1,0) -> #N/A | Z29: =VLOOKUP($U29,'MAY 26'!$C$14:$C$100,1,0) -> #N/A | AA29: =VLOOKUP($U29,'JUN 26'!$C$14:$C$103,1,0) -> #N/A | AB29: =COUNTIF(V29:AA29,U29) -> 0 | AC29: =IF(AB29>0,"SI","NO") -> NO | AD29: =IF(AC29="SI",1,0) -> 0
T30: 6 | U30: WIND IV | V30: =VLOOKUP($U30,'ENE 26'!$C$14:$C$104,1,0) -> #N/A | W30: =VLOOKUP($U30,'FEB 26'!$C$14:$C$100,1,0) -> #N/A | X30: =VLOOKUP($U30,'MAR 26'!$C$14:$C$101,1,0) -> #N/A | Y30: =VLOOKUP($U30,'ABR 26'!$C$14:$C$101,1,0) -> #N/A | Z30: =VLOOKUP($U30,'MAY 26'!$C$14:$C$100,1,0) -> #N/A | AA30: =VLOOKUP($U30,'JUN 26'!$C$14:$C$103,1,0) -> #N/A | AB30: =COUNTIF(V30:AA30,U30) -> 0 | AC30: =IF(AB30>0,"SI","NO") -> NO | AD30: =IF(AC30="SI",1,0) -> 0
B31: FOCO | T31: 7 | U31: SQUAT | V31: =VLOOKUP($U31,'ENE 26'!$C$14:$C$104,1,0) -> #N/A | W31: =VLOOKUP($U31,'FEB 26'!$C$14:$C$100,1,0) -> #N/A | X31: =VLOOKUP($U31,'MAR 26'!$C$14:$C$101,1,0) -> #N/A | Y31: =VLOOKUP($U31,'ABR 26'!$C$14:$C$101,1,0) -> #N/A | Z31: =VLOOKUP($U31,'MAY 26'!$C$14:$C$100,1,0) -> #N/A | AA31: =VLOOKUP($U31,'JUN 26'!$C$14:$C$103,1,0) -> #N/A | AB31: =COUNTIF(V31:AA31,U31) -> 0 | AC31: =IF(AB31>0,"SI","NO") -> NO | AD31: =IF(AC31="SI",1,0) -> 0
B32: Gen. Unif | C32: Categoría | E32: Modelo | F32: VOL | T32: 8 | U32: LISS | V32: =VLOOKUP($U32,'ENE 26'!$C$14:$C$104,1,0) -> #N/A | W32: =VLOOKUP($U32,'FEB 26'!$C$14:$C$100,1,0) -> #N/A | X32: =VLOOKUP($U32,'MAR 26'!$C$14:$C$101,1,0) -> #N/A | Y32: =VLOOKUP($U32,'ABR 26'!$C$14:$C$101,1,0) -> #N/A | Z32: =VLOOKUP($U32,'MAY 26'!$C$14:$C$100,1,0) -> #N/A | AA32: =VLOOKUP($U32,'JUN 26'!$C$14:$C$103,1,0) -> #N/A | AB32: =COUNTIF(V32:AA32,U32) -> 0 | AC32: =IF(AB32>0,"SI","NO") -> NO | AD32: =IF(AC32="SI",1,0) -> 0
B33: Adulto | C33: Casual | E33: X FORCER III | F33: =+SUMIF('ENE 26'!$C$14:$C$111,'RESUMEN CATEGORIAS'!E33,'ENE 26'!$AM$14:$AM$111)+SUMIF('FEB 26'!$C$14:$C$101,'RESUMEN CATEGORIAS'!E33,'FEB 26'!$AM$14:$AM$101)+SUMIF('MAR 26'!$C$14:$C$101,'RESUMEN CATEGORIAS'!E33,'FEB 26'!$AM$14:$AM$101)+SUMIF('ABR 26'!$C$14:$C$101,'RESUMEN CATEGORIAS'!E33,'ABR 26'!$AM$14:$AM$101)+SUMIF('MAY 26'!$C$14:$C$100,'RESUMEN CATEGORIAS'!E33,'MAY 26'!$AM$14:$AM$100)+SUMIF('JUN 26'!$C$14:$C$103,'RESUMEN CATEGORIAS'!E33,'JUN 26'!$AM$14:$AM$103) -> 0
B34: Adulto | C34: Casual | E34: SEGOVIA | F34: =+SUMIF('ENE 26'!$C$14:$C$111,'RESUMEN CATEGORIAS'!E34,'ENE 26'!$AM$14:$AM$111)+SUMIF('FEB 26'!$C$14:$C$101,'RESUMEN CATEGORIAS'!E34,'FEB 26'!$AM$14:$AM$101)+SUMIF('MAR 26'!$C$14:$C$101,'RESUMEN CATEGORIAS'!E34,'FEB 26'!$AM$14:$AM$101)+SUMIF('ABR 26'!$C$14:$C$101,'RESUMEN CATEGORIAS'!E34,'ABR 26'!$AM$14:$AM$101)+SUMIF('MAY 26'!$C$14:$C$100,'RESUMEN CATEGORIAS'!E34,'MAY 26'!$AM$14:$AM$100)+SUMIF('JUN 26'!$C$14:$C$103,'RESUMEN CATEGORIAS'!E34,'JUN 26'!$AM$14:$AM$103) -> 0
B35: Adulto | C35: Casual | E35: TERRE | F35: =+SUMIF('ENE 26'!$C$14:$C$111,'RESUMEN CATEGORIAS'!E35,'ENE 26'!$AM$14:$AM$111)+SUMIF('FEB 26'!$C$14:$C$101,'RESUMEN CATEGORIAS'!E35,'FEB 26'!$AM$14:$AM$101)+SUMIF('MAR 26'!$C$14:$C$101,'RESUMEN CATEGORIAS'!E35,'FEB 26'!$AM$14:$AM$101)+SUMIF('ABR 26'!$C$14:$C$101,'RESUMEN CATEGORIAS'!E35,'ABR 26'!$AM$14:$AM$101)+SUMIF('MAY 26'!$C$14:$C$100,'RESUMEN CATEGORIAS'!E35,'MAY 26'!$AM$14:$AM$100)+SUMIF('JUN 26'!$C$14:$C$103,'RESUMEN CATEGORIAS'!E35,'JUN 26'!$AM$14:$AM$103) -> 0
B36: Adulto | C36: Casual | E36: LEROI | F36: =+SUMIF('ENE 26'!$C$14:$C$111,'RESUMEN CATEGORIAS'!E36,'ENE 26'!$AM$14:$AM$111)+SUMIF('FEB 26'!$C$14:$C$101,'RESUMEN CATEGORIAS'!E36,'FEB 26'!$AM$14:$AM$101)+SUMIF('MAR 26'!$C$14:$C$101,'RESUMEN CATEGORIAS'!E36,'FEB 26'!$AM$14:$AM$101)+SUMIF('ABR 26'!$C$14:$C$101,'RESUMEN CATEGORIAS'!E36,'ABR 26'!$AM$14:$AM$101)+SUMIF('MAY 26'!$C$14:$C$100,'RESUMEN CATEGORIAS'!E36,'MAY 26'!$AM$14:$AM$100)+SUMIF('JUN 26'!$C$14:$C$103,'RESUMEN CATEGORIAS'!E36,'JUN 26'!$AM$14:$AM$103) -> 0
B37: Adulto | C37: Casual | E37: SENY | F37: =+SUMIF('ENE 26'!$C$14:$C$111,'RESUMEN CATEGORIAS'!E37,'ENE 26'!$AM$14:$AM$111)+SUMIF('FEB 26'!$C$14:$C$101,'RESUMEN CATEGORIAS'!E37,'FEB 26'!$AM$14:$AM$101)+SUMIF('MAR 26'!$C$14:$C$101,'RESUMEN CATEGORIAS'!E37,'FEB 26'!$AM$14:$AM$101)+SUMIF('ABR 26'!$C$14:$C$101,'RESUMEN CATEGORIAS'!E37,'ABR 26'!$AM$14:$AM$101)+SUMIF('MAY 26'!$C$14:$C$100,'RESUMEN CATEGORIAS'!E37,'MAY 26'!$AM$14:$AM$100)+SUMIF('JUN 26'!$C$14:$C$103,'RESUMEN CATEGORIAS'!E37,'JUN 26'!$AM$14:$AM$103) -> 36
B38: Adulto | C38: Casual | E38: T-850 | F38: =+SUMIF('ENE 26'!$C$14:$C$111,'RESUMEN CATEGORIAS'!E38,'ENE 26'!$AM$14:$AM$111)+SUMIF('FEB 26'!$C$14:$C$101,'RESUMEN CATEGORIAS'!E38,'FEB 26'!$AM$14:$AM$101)+SUMIF('MAR 26'!$C$14:$C$101,'RESUMEN CATEGORIAS'!E38,'FEB 26'!$AM$14:$AM$101)+SUMIF('ABR 26'!$C$14:$C$101,'RESUMEN CATEGORIAS'!E38,'ABR 26'!$AM$14:$AM$101)+SUMIF('MAY 26'!$C$14:$C$100,'RESUMEN CATEGORIAS'!E38,'MAY 26'!$AM$14:$AM$100)+SUMIF('JUN 26'!$C$14:$C$103,'RESUMEN CATEGORIAS'!E38,'JUN 26'!$AM$14:$AM$103) -> 0
B39: Adulto | C39: Casual | E39: FEINT | F39: =+SUMIF('ENE 26'!$C$14:$C$111,'RESUMEN CATEGORIAS'!E39,'ENE 26'!$AM$14:$AM$111)+SUMIF('FEB 26'!$C$14:$C$101,'RESUMEN CATEGORIAS'!E39,'FEB 26'!$AM$14:$AM$101)+SUMIF('MAR 26'!$C$14:$C$101,'RESUMEN CATEGORIAS'!E39,'FEB 26'!$AM$14:$AM$101)+SUMIF('ABR 26'!$C$14:$C$101,'RESUMEN CATEGORIAS'!E39,'ABR 26'!$AM$14:$AM$101)+SUMIF('MAY 26'!$C$14:$C$100,'RESUMEN CATEGORIAS'!E39,'MAY 26'!$AM$14:$AM$100)+SUMIF('JUN 26'!$C$14:$C$103,'RESUMEN CATEGORIAS'!E39,'JUN 26'!$AM$14:$AM$103) -> 0
B40: Adulto | C40: Running+Training | E40: STRONG PACE 4 | F40: =+SUMIF('ENE 26'!$C$14:$C$111,'RESUMEN CATEGORIAS'!E40,'ENE 26'!$AM$14:$AM$111)+SUMIF('FEB 26'!$C$14:$C$101,'RESUMEN CATEGORIAS'!E40,'FEB 26'!$AM$14:$AM$101)+SUMIF('MAR 26'!$C$14:$C$101,'RESUMEN CATEGORIAS'!E40,'FEB 26'!$AM$14:$AM$101)+SUMIF('ABR 26'!$C$14:$C$101,'RESUMEN CATEGORIAS'!E40,'ABR 26'!$AM$14:$AM$101)+SUMIF('MAY 26'!$C$14:$C$100,'RESUMEN CATEGORIAS'!E40,'MAY 26'!$AM$14:$AM$100)+SUMIF('JUN 26'!$C$14:$C$103,'RESUMEN CATEGORIAS'!E40,'JUN 26'!$AM$14:$AM$103) -> 146
B41: Adulto | C41: Running+Training | E41: SQUAT II | F41: =+SUMIF('ENE 26'!$C$14:$C$111,'RESUMEN CATEGORIAS'!E41,'ENE 26'!$AM$14:$AM$111)+SUMIF('FEB 26'!$C$14:$C$101,'RESUMEN CATEGORIAS'!E41,'FEB 26'!$AM$14:$AM$101)+SUMIF('MAR 26'!$C$14:$C$101,'RESUMEN CATEGORIAS'!E41,'FEB 26'!$AM$14:$AM$101)+SUMIF('ABR 26'!$C$14:$C$101,'RESUMEN CATEGORIAS'!E41,'ABR 26'!$AM$14:$AM$101)+SUMIF('MAY 26'!$C$14:$C$100,'RESUMEN CATEGORIAS'!E41,'MAY 26'!$AM$14:$AM$100)+SUMIF('JUN 26'!$C$14:$C$103,'RESUMEN CATEGORIAS'!E41,'JUN 26'!$AM$14:$AM$103) -> 104
B42: Adulto | C42: Running+Training | E42: STANCE 3 | F42: =+SUMIF('ENE 26'!$C$14:$C$111,'RESUMEN CATEGORIAS'!E42,'ENE 26'!$AM$14:$AM$111)+SUMIF('FEB 26'!$C$14:$C$101,'RESUMEN CATEGORIAS'!E42,'FEB 26'!$AM$14:$AM$101)+SUMIF('MAR 26'!$C$14:$C$101,'RESUMEN CATEGORIAS'!E42,'FEB 26'!$AM$14:$AM$101)+SUMIF('ABR 26'!$C$14:$C$101,'RESUMEN CATEGORIAS'!E42,'ABR 26'!$AM$14:$AM$101)+SUMIF('MAY 26'!$C$14:$C$100,'RESUMEN CATEGORIAS'!E42,'MAY 26'!$AM$14:$AM$100)+SUMIF('JUN 26'!$C$14:$C$103,'RESUMEN CATEGORIAS'!E42,'JUN 26'!$AM$14:$AM$103) -> 30
B43: Adulto | C43: Running+Training | E43: WIND 5 | F43: =+SUMIF('ENE 26'!$C$14:$C$111,'RESUMEN CATEGORIAS'!E43,'ENE 26'!$AM$14:$AM$111)+SUMIF('FEB 26'!$C$14:$C$101,'RESUMEN CATEGORIAS'!E43,'FEB 26'!$AM$14:$AM$101)+SUMIF('MAR 26'!$C$14:$C$101,'RESUMEN CATEGORIAS'!E43,'FEB 26'!$AM$14:$AM$101)+SUMIF('ABR 26'!$C$14:$C$101,'RESUMEN CATEGORIAS'!E43,'ABR 26'!$AM$14:$AM$101)+SUMIF('MAY 26'!$C$14:$C$100,'RESUMEN CATEGORIAS'!E43,'MAY 26'!$AM$14:$AM$100)+SUMIF('JUN 26'!$C$14:$C$103,'RESUMEN CATEGORIAS'!E43,'JUN 26'!$AM$14:$AM$103) -> 90
...

Sheet ENE 26
C1: NOTA DE PEDIDO - 1° SEMESTRE 2026 (Enero - Junio)
C3: Clase | D3: ZPR
C5: Razon Social | D5: =+IF(D7="","",(VLOOKUP(D7,AUX!$A$1:$B$5610,2,FALSE)))
C7: N° Cliente | I7: TOTALES
D9: =+AUX!J3 -> ENE 2026 | I9: Pares | J9: =+AM9 -> 302 | L9: $ | M9: =+AM9 -> 302 | AM9: =SUM(AM14:AM104) -> 302 | AO9: =SUM(AO14:AO104) -> 10926096
H11: NRO | J11: MES | L11: 200 | M11: 210 | N11: 220 | O11: 230 | P11: 240 | Q11: 250 | R11: 260 | S11: 270 | T11: 280 | U11: 290 | V11: 300 | W11: 310 | X11: 320 | Y11: 330 | Z11: 340 | AA11: 350 | AB11: 360 | AC11: 370 | AD11: 380 | AE11: 390 | AF11: 400 | AG11: 410 | AH11: 420 | AI11: 430 | AJ11: 440 | AK11: 450 | AL11: 460 | AM11: CANT | AN11: Precio | AO11: $
H12: ARTICULO | J12: LANZAMIENTO | AM12: TOTAL | AN12: Lista | AO12: TOTAL | XEO12: =+SUM(XEO14:XEO104) -> 64 | XEP12: =+SUM(XEP14:XEP104) -> 0 | XEQ12: =+SUM(XEQ14:XEQ104) -> 0 | XER12: =+SUM(XER14:XER104) -> 66
A13: GENERO | C13: MODELO | D13: COLOR | E13: DISPONIBILIDAD | F13: TALLES | G13: PVP | AP13: CATEGORIA | AQ13: MIX CALZ | XEO13: CASUAL | XEP13: RUN/TRA | XEQ13: MULTI | XER13: KIDS
A14: =IF($I14>0,VLOOKUP(I14,'Lista de Precios'!$A$3:$L$2883,9,0),0) -> Hombre | B14: =IF($I14>0,VLOOKUP(I14,'Lista de Precios'!$A$3:$H$2883,7,0),0) -> CONT | C14: =IF($I14>0,VLOOKUP(I14,'Lista de Precios'!$A$3:$H$2883,2,0),"") -> FAST 2.0 | D14: =IF($I14>0,VLOOKUP(I14,'Lista de Precios'!$A$3:$H$2883,3,0),"") -> NEGRO/GRIS MAGNET/BLANCO | E14: =IF($I14>0,VLOOKUP(I14,'Lista de Precios'!$A$3:$H$2883,6,0),"") -> ENERO | F14: =IF($I14>0,VLOOKUP(I14,'Lista de Precios'!$A$3:$H$2883,8,0),"") -> 35 AL 46 | G14: =IF(AN14="","",AN14*1.87) -> 74900 | H14: 0 | I14: 25860 | J14: =+E14 -> ENERO | AF14: 4 | AG14: 6 | AH14: 4 | AI14: 4 | AK14: 2 | AL14: 2 | AM14: =+IF(I14>0,SUM(L14:AL14),0) -> 22 | AN14: =+IF($I14>0,VLOOKUP($I14,'Lista de Precios'!$A$3:$H$2883,4,0),"") -> 40053.476 | AO14: =+IF(AM14>0,AN14*AM14,"") -> 881176.47 | AP14: =IF($I14>0,VLOOKUP($I14,'Lista de Precios'!$A$3:$K$2883,10,0),"") -> Running | AQ14: =IF($I14>0,VLOOKUP($I14,'Lista de Precios'!$A$3:$M$49893,13,0),"") -> Running+Training | XEO14: =+IF($AQ14=$XEO$13,$AM14,"") | XEP14: =+IF($AQ14=$XEP$13,$AM14,"") | XEQ14: =+IF($AQ14=$XEQ$13,$AM14,"") | XER14: =+IF($AQ14=$XER$13,$AM14,"")
A15: =IF($I15>0,VLOOKUP(I15,'Lista de Precios'!$A$3:$L$2883,9,0),0) -> Hombre | B15: =IF($I15>0,VLOOKUP(I15,'Lista de Precios'!$A$3:$H$2883,7,0),0) -> CONT | C15: =IF($I15>0,VLOOKUP(I15,'Lista de Precios'!$A$3:$H$2883,2,0),"") -> WIND 5 | D15: =IF($I15>0,VLOOKUP(I15,'Lista de Precios'!$A$3:$H$2883,3,0),"") -> NEGRO/GRIS | E15: =IF($I15>0,VLOOKUP(I15,'Lista de Precios'!$A$3:$H$2883,6,0),"") -> ENERO | F15: =IF($I15>0,VLOOKUP(I15,'Lista de Precios'!$A$3:$H$2883,8,0),"") -> 35 AL 45 | G15: =IF(AN15="","",AN15*1.87) -> 68900 | H15: 0 | I15: 25787 | J15: =+E15 -> ENERO | AA15: 2 | AB15: 4 | AC15: 6 | AD15: 8 | AE15: 8 | AF15: 6 | AK15: 2 | AL15: 2 | AM15: =+IF(I15>0,SUM(L15:AL15),0) -> 38 | AN15: =+IF($I15>0,VLOOKUP($I15,'Lista de Precios'!$A$3:$H$2883,4,0),"") -> 36844.92 | AO15: =+IF(AM15>0,AN15*AM15,"") -> 1400107 | AP15: =IF($I15>0,VLOOKUP($I15,'Lista de Precios'!$A$3:$K$2883,10,0),"") -> Running | AQ15: =IF($I15>0,VLOOKUP($I15,'Lista de Precios'!$A$3:$M$49893,13,0),"") -> Running+Training | XEO15: =+IF($AQ15=$XEO$13,$AM15,"") | XEP15: =+IF($AQ15=$XEP$13,$AM15,"") | XEQ15: =+IF($AQ15=$XEQ$13,$AM15,"") | XER15: =+IF($AQ15=$XER$13,$AM15,"")
A16: =IF($I16>0,VLOOKUP(I16,'Lista de Precios'!$A$3:$L$2883,9,0),0) -> Hombre | B16: =IF($I16>0,VLOOKUP(I16,'Lista de Precios'!$A$3:$H$2883,7,0),0) -> CONT | C16: =IF($I16>0,VLOOKUP(I16,'Lista de Precios'!$A$3:$H$2883,2,0),"") -> WIND 5 | D16: =IF($I16>0,VLOOKUP(I16,'Lista de Precios'!$A$3:$H$2883,3,0),"") -> AZUL PAG/BLANCO | E16: =IF($I16>0,VLOOKUP(I16,'Lista de Precios'!$A$3:$H$2883,6,0),"") -> ENERO | F16: =IF($I16>0,VLOOKUP(I16,'Lista de Precios'!$A$3:$H$2883,8,0),"") -> 35 AL 45 | G16: =IF(AN16="","",AN16*1.87) -> 68900 | H16: 0 | I16: 26445 | J16: =+E16 -> ENERO | AC16: 2 | AD16: 4 | AE16: 6 | AF16: 4 | AG16: 6 | AM16: =+IF(I16>0,SUM(L16:AL16),0) -> 22 | AN16: =+IF($I16>0,VLOOKUP($I16,'Lista de Precios'!$A$3:$H$2883,4,0),"") -> 36844.92 | AO16: =+IF(AM16>0,AN16*AM16,"") -> 810588.24 | AP16: =IF($I16>0,VLOOKUP($I16,'Lista de Precios'!$A$3:$K$2883,10,0),"") -> Running | AQ16: =IF($I16>0,VLOOKUP($I16,'Lista de Precios'!$A$3:$M$49893,13,0),"") -> Running+Training | XEO16: =+IF($AQ16=$XEO$13,$AM16,"") | XEP16: =+IF($AQ16=$XEP$13,$AM16,"") | XEQ16: =+IF($AQ16=$XEQ$13,$AM16,"") | XER16: =+IF($AQ16=$XER$13,$AM16,"")
A17: =IF($I17>0,VLOOKUP(I17,'Lista de Precios'!$A$3:$L$2883,9,0),0) -> Mujer | B17: =IF($I17>0,VLOOKUP(I17,'Lista de Precios'!$A$3:$H$2883,7,0),0) -> CONT | C17: =IF($I17>0,VLOOKUP(I17,'Lista de Precios'!$A$3:$H$2883,2,0),"") -> SENDAI | D17: =IF($I17>0,VLOOKUP(I17,'Lista de Precios'!$A$3:$H$2883,3,0),"") -> GRIS MAGNET/NEGRO/ROSA PEAC | E17: =IF($I17>0,VLOOKUP(I17,'Lista de Precios'!$A$3:$H$2883,6,0),"") -> ENERO | F17: =IF($I17>0,VLOOKUP(I17,'Lista de Precios'!$A$3:$H$2883,8,0),"") -> 35 AL 40 | G17: =IF(AN17="","",AN17*1.87) -> 73900 | H17: 0 | I17: 26903 | J17: =+E17 -> ENERO | AB17: 4 | AC17: 8 | AD17: 12 | AE17: 12 | AF17: 8 | AM17: =+IF(I17>0,SUM(L17:AL17),0) -> 44 | AN17: =+IF($I17>0,VLOOKUP($I17,'Lista de Precios'!$A$3:$H$2883,4,0),"") -> 39518.717 | AO17: =+IF(AM17>0,AN17*AM17,"") -> 1738823.5 | AP17: =IF($I17>0,VLOOKUP($I17,'Lista de Precios'!$A$3:$K$2883,10,0),"") -> Casual | AQ17: =IF($I17>0,VLOOKUP($I17,'Lista de Precios'!$A$3:$M$49893,13,0),"") -> Casual | XEO17: =+IF($AQ17=$XEO$13,$AM17,"") -> 44 | XEP17: =+IF($AQ17=$XEP$13,$AM17,"") | XEQ17: =+IF($AQ17=$XEQ$13,$AM17,"") | XER17: =+IF($AQ17=$XER$13,$AM17,"")
A18: =IF($I18>0,VLOOKUP(I18,'Lista de Precios'!$A$3:$L$2883,9,0),0) -> Unisex | B18: =IF($I18>0,VLOOKUP(I18,'Lista de Precios'!$A$3:$H$2883,7,0),0) -> CONT | C18: =IF($I18>0,VLOOKUP(I18,'Lista de Precios'!$A$3:$H$2883,2,0),"") -> SENDAI | D18: =IF($I18>0,VLOOKUP(I18,'Lista de Precios'!$A$3:$H$2883,3,0),"") -> MORN/ETHEREA | E18: =IF($I18>0,VLOOKUP(I18,'Lista de Precios'!$A$3:$H$2883,6,0),"") -> ENERO | F18: =IF($I18>0,VLOOKUP(I18,'Lista de Precios'!$A$3:$H$2883,8,0),"") -> 35 AL 45 | G18: =IF(AN18="","",AN18*1.87) -> 73900 | H18: 0 | I18: 26902 | J18: =+E18 -> ENERO | AC18: 4 | AD18: 6 | AE18: 4 | AF18: 6 | AM18: =+IF(I18>0,SUM(L18:AL18),0) -> 20 | AN18: =+IF($I18>0,VLOOKUP($I18,'Lista de Precios'!$A$3:$H$2883,4,0),"") -> 39518.717 | AO18: =+IF(AM18>0,AN18*AM18,"") -> 790374.33 | AP18: =IF($I18>0,VLOOKUP($I18,'Lista de Precios'!$A$3:$K$2883,10,0),"") -> Casual | AQ18: =IF($I18>0,VLOOKUP($I18,'Lista de Precios'!$A$3:$M$49893,13,0),"") -> Casual | XEO18: =+IF($AQ18=$XEO$13,$AM18,"") -> 20 | XEP18: =+IF($AQ18=$XEP$13,$AM18,"") | XEQ18: =+IF($AQ18=$XEQ$13,$AM18,"") | XER18: =+IF($AQ18=$XER$13,$AM18,"")
A19: =IF($I19>0,VLOOKUP(I19,'Lista de Precios'!$A$3:$L$2883,9,0),0) -> Kids | B19: =IF($I19>0,VLOOKUP(I19,'Lista de Precios'!$A$3:$H$2883,7,0),0) -> CONT | C19: =IF($I19>0,VLOOKUP(I19,'Lista de Precios'!$A$3:$H$2883,2,0),"") -> ITEN KIDS | D19: =IF($I19>0,VLOOKUP(I19,'Lista de Precios'!$A$3:$H$2883,3,0),"") -> NEGRO / VERDE WAVE | E19: =IF($I19>0,VLOOKUP(I19,'Lista de Precios'!$A$3:$H$2883,6,0),"") -> ENERO | F19: =IF($I19>0,VLOOKUP(I19,'Lista de Precios'!$A$3:$H$2883,8,0),"") -> 25 AL 34 | G19: =IF(AN19="","",AN19*1.87) -> 61900 | H19: 27342 | I19: 89578 | J19: =+E19 -> ENERO | Q19: 4 | R19: 4 | S19: 2 | T19: 4 | U19: 2 | V19: 4 | W19: 2 | X19: 2 | Y19: 2 | Z19: 2 | AM19: =+IF(I19>0,SUM(L19:AL19),0) -> 28 | AN19: =+IF($I19>0,VLOOKUP($I19,'Lista de Precios'!$A$3:$H$2883,4,0),"") -> 33101.604 | AO19: =+IF(AM19>0,AN19*AM19,"") -> 926844.92 | AP19: =IF($I19>0,VLOOKUP($I19,'Lista de Precios'!$A$3:$K$2883,10,0),"") -> Running | AQ19: =IF($I19>0,VLOOKUP($I19,'Lista de Precios'!$A$3:$M$49893,13,0),"") -> Kids | XEO19: =+IF($AQ19=$XEO$13,$AM19,"") | XEP19: =+IF($AQ19=$XEP$13,$AM19,"") | XEQ19: =+IF($AQ19=$XEQ$13,$AM19,"") | XER19: =+IF($AQ19=$XER$13,$AM19,"") -> 28
A20: =IF($I20>0,VLOOKUP(I20,'Lista de Precios'!$A$3:$L$2883,9,0),0) -> Kids | B20: =IF($I20>0,VLOOKUP(I20,'Lista de Precios'!$A$3:$H$2883,7,0),0) -> CONT | C20: =IF($I20>0,VLOOKUP(I20,'Lista de Precios'!$A$3:$H$2883,2,0),"") -> ZURICH III KIDS | D20: =IF($I20>0,VLOOKUP(I20,'Lista de Precios'!$A$3:$H$2883,3,0),"") -> NEGRO | E20: =IF($I20>0,VLOOKUP(I20,'Lista de Precios'!$A$3:$H$2883,6,0),"") -> ENERO | F20: =IF($I20>0,VLOOKUP(I20,'Lista de Precios'!$A$3:$H$2883,8,0),"") -> 25 AL 34 | G20: =IF(AN20="","",AN20*1.87) -> 52900 | H20: 0 | I20: 26320 | J20: =+E20 -> ENERO | R20: 4 | S20: 2 | T20: 6 | U20: 6 | V20: 6 | W20: 2 | X20: 4 | Y20: 4 | Z20: 4 | AM20: =+IF(I20>0,SUM(L20:AL20),0) -> 38 | AN20: =+IF($I20>0,VLOOKUP($I20,'Lista de Precios'!$A$3:$H$2883,4,0),"") -> 28288.77 | AO20: =+IF(AM20>0,AN20*AM20,"") -> 1074973.3 | AP20: =IF($I20>0,VLOOKUP($I20,'Lista de Precios'!$A$3:$K$2883,10,0),"") -> Running | AQ20: =IF($I20>0,VLOOKUP($I20,'Lista de Precios'!$A$3:$M$49893,13,0),"") -> Kids | XEO20: =+IF($AQ20=$XEO$13,$AM20,"") | XEP20: =+IF($AQ20=$XEP$13,$AM20,"") | XEQ20: =+IF($AQ20=$XEQ$13,$AM20,"") | XER20: =+IF($AQ20=$XER$13,$AM20,"") -> 38
A21: =IF($I21>0,VLOOKUP(I21,'Lista de Precios'!$A$3:$L$2883,9,0),0) -> 0 | B21: =IF($I21>0,VLOOKUP(I21,'Lista de Precios'!$A$3:$H$2883,7,0),0) -> 0 | C21: =IF($I21>0,VLOOKUP(I21,'Lista de Precios'!$A$3:$H$2883,2,0),"") | D21: =IF($I21>0,VLOOKUP(I21,'Lista de Precios'!$A$3:$H$2883,3,0),"") | E21: =IF($I21>0,VLOOKUP(I21,'Lista de Precios'!$A$3:$H$2883,6,0),"") | F21: =IF($I21>0,VLOOKUP(I21,'Lista de Precios'!$A$3:$H$2883,8,0),"") | G21: =IF(AN21="","",AN21*1.87) | H21: 0 | J21: =+E21 | AM21: =+IF(I21>0,SUM(L21:AL21),0) -> 0 | AN21: =+IF($I21>0,VLOOKUP($I21,'Lista de Precios'!$A$3:$H$2883,4,0),"") | AO21: =+IF(AM21>0,AN21*AM21,"") | AP21: =IF($I21>0,VLOOKUP($I21,'Lista de Precios'!$A$3:$K$2883,10,0),"") | AQ21: =IF($I21>0,VLOOKUP($I21,'Lista de Precios'!$A$3:$M$49893,13,0),"") | XEO21: =+IF($AQ21=$XEO$13,$AM21,"") | XEP21: =+IF($AQ21=$XEP$13,$AM21,"") | XEQ21: =+IF($AQ21=$XEQ$13,$AM21,"") | XER21: =+IF($AQ21=$XER$13,$AM21,"")
A22: =IF($I22>0,VLOOKUP(I22,'Lista de Precios'!$A$3:$L$2883,9,0),0) -> Hombre | B22: =IF($I22>0,VLOOKUP(I22,'Lista de Precios'!$A$3:$H$2883,7,0),0) -> CONT | C22: =IF($I22>0,VLOOKUP(I22,'Lista de Precios'!$A$3:$H$2883,2,0),"") -> DRIVE 2 | D22: =IF($I22>0,VLOOKUP(I22,'Lista de Precios'!$A$3:$H$2883,3,0),"") -> NEGRO/GRIS VANE | E22: =IF($I22>0,VLOOKUP(I22,'Lista de Precios'!$A$3:$H$2883,6,0),"") -> ENERO | F22: =IF($I22>0,VLOOKUP(I22,'Lista de Precios'!$A$3:$H$2883,8,0),"") -> 35 AL 45 | G22: =IF(AN22="","",AN22*1.87) -> 78900 | H22: 0 | I22: 26555 | J22: =+E22 -> ENERO | AA22: 2 | AB22: 2 | AM22: =+IF(I22>0,SUM(L22:AL22),0) -> 4 | AN22: =+IF($I22>0,VLOOKUP($I22,'Lista de Precios'!$A$3:$H$2883,4,0),"") -> 42192.513 | AO22: =+IF(AM22>0,AN22*AM22,"") -> 168770.05 | AP22: =IF($I22>0,VLOOKUP($I22,'Lista de Precios'!$A$3:$K$2883,10,0),"") -> Training | AQ22: =IF($I22>0,VLOOKUP($I22,'Lista de Precios'!$A$3:$M$49893,13,0),"") -> Running+Training | XEO22: =+IF($AQ22=$XEO$13,$AM22,"") | XEP22: =+IF($AQ22=$XEP$13,$AM22,"") | XEQ22: =+IF($AQ22=$XEQ$13,$AM22,"") | XER22: =+IF($AQ22=$XER$13,$AM22,"")
A23: =IF($I23>0,VLOOKUP(I23,'Lista de Precios'!$A$3:$L$2883,9,0),0) -> Mujer | B23: =IF($I23>0,VLOOKUP(I23,'Lista de Precios'!$A$3:$H$2883,7,0),0) -> CONT | C23: =IF($I23>0,VLOOKUP(I23,'Lista de Precios'!$A$3:$H$2883,2,0),"") -> DRIVE 2 | D23: =IF($I23>0,VLOOKUP(I23,'Lista de Precios'!$A$3:$H$2883,3,0),"") -> ROSA HUSH/ROSA SHAPE | E23: =IF($I23>0,VLOOKUP(I23,'Lista de Precios'!$A$3:$H$2883,6,0),"") -> ENERO | F23: =IF($I23>0,VLOOKUP(I23,'Lista de Precios'!$A$3:$H$2883,8,0),"") -> 35 AL 40 | G23: =IF(AN23="","",AN23*1.87) -> 78900 | H23: 0 | I23: 26448 | J23: =+E23 -> ENERO | AB23: 2 | AC23: 8 | AD23: 8 | AE23: 6 | AF23: 6 | AM23: =+IF(I23>0,SUM(L23:AL23),0) -> 30 | AN23: =+IF($I23>0,VLOOKUP($I23,'Lista de Precios'!$A$3:$H$2883,4,0),"") -> 42192.513 | AO23: =+IF(AM23>0,AN23*AM23,"") -> 1265775.4 | AP23: =IF($I23>0,VLOOKUP($I23,'Lista de Precios'!$A$3:$K$2883,10,0),"") -> Training | AQ23: =IF($I23>0,VLOOKUP($I23,'Lista de Precios'!$A$3:$M$49893,13,0),"") -> Running+Training | XEO23: =+IF($AQ23=$XEO$13,$AM23,"") | XEP23: =+IF($AQ23=$XEP$13,$AM23,"") | XEQ23: =+IF($AQ23=$XEQ$13,$AM23,"") | XER23: =+IF($AQ23=$XER$13,$AM23,"")
A24: =IF($I24>0,VLOOKUP(I24,'Lista de Precios'!$A$3:$L$2883,9,0),0) -> Hombre | B24: =IF($I24>0,VLOOKUP(I24,'Lista de Precios'!$A$3:$H$2883,7,0),0) -> CONT | C24: =IF($I24>0,VLOOKUP(I24,'Lista de Precios'!$A$3:$H$2883,2,0),"") -> STRONG PACE III | D24: =IF($I24>0,VLOOKUP(I24,'Lista de Precios'!$A$3:$H$2883,3,0),"") -> NEGRO/LIMA SPRING | E24: =IF($I24>0,VLOOKUP(I24,'Lista de Precios'!$A$3:$H$2883,6,0),"") -> ENERO | F24: =IF($I24>0,VLOOKUP(I24,'Lista de Precios'!$A$3:$H$2883,8,0),"") -> 35 AL 46 | G24: =IF(AN24="","",AN24*1.87) -> 62900 | H24: 0 | I24: 26205 | J24: =+E24 -> ENERO | AF24: 4 | AG24: 6 | AH24: 4 | AI24: 2 | AK24: 2 | AM24: =+IF(I24>0,SUM(L24:AL24),0) -> 18 | AN24: =+IF($I24>0,VLOOKUP($I24,'Lista de Precios'!$A$3:$H$2883,4,0),"") -> 33636.364 | AO24: =+IF(AM24>0,AN24*AM24,"") -> 605454.55 | AP24: =IF($I24>0,VLOOKUP($I24,'Lista de Precios'!$A$3:$K$2883,10,0),"") -> Training | AQ24: =IF($I24>0,VLOOKUP($I24,'Lista de Precios'!$A$3:$M$49893,13,0),"") -> Running+Training | XEO24: =+IF($AQ24=$XEO$13,$AM24,"") | XEP24: =+IF($AQ24=$XEP$13,$AM24,"") | XEQ24: =+IF($AQ24=$XEQ$13,$AM24,"") | XER24: =+IF($AQ24=$XER$13,$AM24,"")
A25: =IF($I25>0,VLOOKUP(I25,'Lista de Precios'!$A$3:$L$2883,9,0),0) -> Mujer | B25: =IF($I25>0,VLOOKUP(I25,'Lista de Precios'!$A$3:$H$2883,7,0),0) -> CONT | C25: =IF($I25>0,VLOOKUP(I25,'Lista de Precios'!$A$3:$H$2883,2,0),"") -> STRONG PACE III | D25: =IF($I25>0,VLOOKUP(I25,'Lista de Precios'!$A$3:$H$2883,3,0),"") -> GRIS CHIP/LILA LAV | E25: =IF($I25>0,VLOOKUP(I25,'Lista de Precios'!$A$3:$H$2883,6,0),"") -> ENERO | F25: =IF($I25>0,VLOOKUP(I25,'Lista de Precios'!$A$3:$H$2883,8,0),"") -> 35 AL 40 | G25: =IF(AN25="","",AN25*1.87) -> 62900 | H25: 0 | I25: 26221 | J25: =+E25 -> ENERO | AC25: 2 | AD25: 4 | AE25: 2 | AF25: 2 | AM25: =+IF(I25>0,SUM(L25:AL25),0) -> 10 | AN25: =+IF($I25>0,VLOOKUP($I25,'Lista de Precios'!$A$3:$H$2883,4,0),"") -> 33636.364 | AO25: =+IF(AM25>0,AN25*AM25,"") -> 336363.64 | AP25: =IF($I25>0,VLOOKUP($I25,'Lista de Precios'!$A$3:$K$2883,10,0),"") -> Training | AQ25: =IF($I25>0,VLOOKUP($I25,'Lista de Precios'!$A$3:$M$49893,13,0),"") -> Running+Training | XEO25: =+IF($AQ25=$XEO$13,$AM25,"") | XEP25: =+IF($AQ25=$XEP$13,$AM25,"") | XEQ25: =+IF($AQ25=$XEQ$13,$AM25,"") | XER25: =+IF($AQ25=$XER$13,$AM25,"")
A26: =IF($I26>0,VLOOKUP(I26,'Lista de Precios'!$A$3:$L$2883,9,0),0) -> 0 | B26: =IF($I26>0,VLOOKUP(I26,'Lista de Precios'!$A$3:$H$2883,7,0),0) -> 0 | C26: =IF($I26>0,VLOOKUP(I26,'Lista de Precios'!$A$3:$H$2883,2,0),"") | D26: =IF($I26>0,VLOOKUP(I26,'Lista de Precios'!$A$3:$H$2883,3,0),"") | E26: =IF($I26>0,VLOOKUP(I26,'Lista de Precios'!$A$3:$H$2883,6,0),"") | F26: =IF($I26>0,VLOOKUP(I26,'Lista de Precios'!$A$3:$H$2883,8,0),"") | G26: =IF(AN26="","",AN26*1.87) | H26: 0 | J26: =+E26 | AM26: =+IF(I26>0,SUM(L26:AL26),0) -> 0 | AN26: =+IF($I26>0,VLOOKUP($I26,'Lista de Precios'!$A$3:$H$2883,4,0),"") | AO26: =+IF(AM26>0,AN26*AM26,"") | AP26: =IF($I26>0,VLOOKUP($I26,'Lista de Precios'!$A$3:$K$2883,10,0),"") | AQ26: =IF($I26>0,VLOOKUP($I26,'Lista de Precios'!$A$3:$M$49893,13,0),"") | XEO26: =+IF($AQ26=$XEO$13,$AM26,"") | XEP26: =+IF($AQ26=$XEP$13,$AM26,"") | XEQ26: =+IF($AQ26=$XEQ$13,$AM26,"") | XER26: =+IF($AQ26=$XER$13,$AM26,"")
A27: =IF($I27>0,VLOOKUP(I27,'Lista de Precios'!$A$3:$L$2883,9,0),0) -> Hombre | B27: =IF($I27>0,VLOOKUP(I27,'Lista de Precios'!$A$3:$H$2883,7,0),0) -> CONT | C27: =IF($I27>0,VLOOKUP(I27,'Lista de Precios'!$A$3:$H$2883,2,0),"") -> SAN CIRO V FG | D27: =IF($I27>0,VLOOKUP(I27,'Lista de Precios'!$A$3:$H$2883,3,0),"") -> NEGRO | E27: =IF($I27>0,VLOOKUP(I27,'Lista de Precios'!$A$3:$H$2883,6,0),"") -> ENERO | F27: =IF($I27>0,VLOOKUP(I27,'Lista de Precios'!$A$3:$H$2883,8,0),"") -> 35 AL 46 | G27: =IF(AN27="","",AN27*1.87) -> 61900 | H27: 0 | I27: 25884 | J27: =+E27 -> ENERO | AD27: 4 | AH27: 4 | AM27: =+IF(I27>0,SUM(L27:AL27),0) -> 8 | AN27: =+IF($I27>0,VLOOKUP($I27,'Lista de Precios'!$A$3:$H$2883,4,0),"") -> 33101.604 | AO27: =+IF(AM27>0,AN27*AM27,"") -> 264812.83 | AP27: =IF($I27>0,VLOOKUP($I27,'Lista de Precios'!$A$3:$K$2883,10,0),"") -> Futbol | AQ27: =IF($I27>0,VLOOKUP($I27,'Lista de Precios'!$A$3:$M$49893,13,0),"") -> Multideporte | XEO27: =+IF($AQ27=$XEO$13,$AM27,"") | XEP27: =+IF($AQ27=$XEP$13,$AM27,"") | XEQ27: =+IF($AQ27=$XEQ$13,$AM27,"") | XER27: =+IF($AQ27=$XER$13,$AM27,"")
A28: =IF($I28>0,VLOOKUP(I28,'Lista de Precios'!$A$3:$L$2883,9,0),0) -> Hombre | B28: =IF($I28>0,VLOOKUP(I28,'Lista de Precios'!$A$3:$H$2883,7,0),0) -> CONT | C28: =IF($I28>0,VLOOKUP(I28,'Lista de Precios'!$A$3:$H$2883,2,0),"") -> SAN CIRO V TF | D28: =IF($I28>0,VLOOKUP(I28,'Lista de Precios'!$A$3:$H$2883,3,0),"") -> NEGRO | E28: =IF($I28>0,VLOOKUP(I28,'Lista de Precios'!$A$3:$H$2883,6,0),"") -> ENERO | F28: =IF($I28>0,VLOOKUP(I28,'Lista de Precios'!$A$3:$H$2883,8,0),"") -> 35 AL 46 | G28: =IF(AN28="","",AN28*1.87) -> 61900 | H28: 0 | I28: 25886 | J28: =+E28 -> ENERO | AG28: 4 | AH28: 6 | AI28: 2 | AN28: =+IF($I28>0,VLOOKUP($I28,'Lista de Precios'!$A$3:$H$2883,4,0),"") -> 33101.604 | AO28: =+IF(AM28>0,AN28*AM28,"") | AP28: =IF($I28>0,VLOOKUP($I28,'Lista de Precios'!$A$3:$K$2883,10,0),"") -> Futbol | AQ28: =IF($I28>0,VLOOKUP($I28,'Lista de Precios'!$A$3:$M$49893,13,0),"") -> Multideporte | XEO28: =+IF($AQ28=$XEO$13,$AM28,"") | XEP28: =+IF($AQ28=$XEP$13,$AM28,"") | XEQ28: =+IF($AQ28=$XEQ$13,$AM28,"") | XER28: =+IF($AQ28=$XER$13,$AM28,"")
A29: =IF($I29>0,VLOOKUP(I29,'Lista de Precios'!$A$3:$L$2883,9,0),0) -> Hombre | B29: =IF($I29>0,VLOOKUP(I29,'Lista de Precios'!$A$3:$H$2883,7,0),0) -> CONT | C29: =IF($I29>0,VLOOKUP(I29,'Lista de Precios'!$A$3:$H$2883,2,0),"") -> SAN CIRO V TF | D29: =IF($I29>0,VLOOKUP(I29,'Lista de Precios'!$A$3:$H$2883,3,0),"") -> BLANCO / NEGRO | E29: =IF($I29>0,VLOOKUP(I29,'Lista de Precios'!$A$3:$H$2883,6,0),"") -> ENERO | F29: =IF($I29>0,VLOOKUP(I29,'Lista de Precios'!$A$3:$H$2883,8,0),"") -> 35 AL 46 | G29: =IF(AN29="","",AN29*1.87) -> 61900 | H29: 0 | I29: 26459 | J29: =+E29 -> ENERO | AC29: 2 | AG29: 4 | AH29: 4 | AM29: =+IF(I29>0,SUM(L29:AL29),0) -> 10 | AN29: =+IF($I29>0,VLOOKUP($I29,'Lista de Precios'!$A$3:$H$2883,4,0),"") -> 33101.604 | AO29: =+IF(AM29>0,AN29*AM29,"") -> 331016.04 | AP29: =IF($I29>0,VLOOKUP($I29,'Lista de Precios'!$A$3:$K$2883,10,0),"") -> Futbol | AQ29: =IF($I29>0,VLOOKUP($I29,'Lista de Precios'!$A$3:$M$49893,13,0),"") -> Multideporte | XEO29: =+IF($AQ29=$XEO$13,$AM29,"") | XEP29: =+IF($AQ29=$XEP$13,$AM29,"") | XEQ29: =+IF($AQ29=$XEQ$13,$AM29,"") | XER29: =+IF($AQ29=$XER$13,$AM29,"")
A30: =IF($I30>0,VLOOKUP(I30,'Lista de Precios'!$A$3:$L$2883,9,0),0) -> Hombre | B30: =IF($I30>0,VLOOKUP(I30,'Lista de Precios'!$A$3:$H$2883,7,0),0) -> CONT | C30: =IF($I30>0,VLOOKUP(I30,'Lista de Precios'!$A$3:$H$2883,2,0),"") -> SAN CIRO V FG | D30: =IF($I30>0,VLOOKUP(I30,'Lista de Precios'!$A$3:$H$2883,3,0),"") -> BLANCO / NEGRO | E30: =IF($I30>0,VLOOKUP(I30,'Lista de Precios'!$A$3:$H$2883,6,0),"") -> ENERO | F30: =IF($I30>0,VLOOKUP(I30,'Lista de Precios'!$A$3:$H$2883,8,0),"") -> 35 AL 46 | G30: =IF(AN30="","",AN30*1.87) -> 61900 | H30: 0 | I30: 26458 | J30: =+E30 -> ENERO | AC30: 4 | AF30: 4 | AG30: 2 | AM30: =+IF(I30>0,SUM(L30:AL30),0) -> 10 | AN30: =+IF($I30>0,VLOOKUP($I30,'Lista de Precios'!$A$3:$H$2883,4,0),"") -> 33101.604 | AO30: =+IF(AM30>0,AN30*AM30,"") -> 331016.04 | AP30: =IF($I30>0,VLOOKUP($I30,'Lista de Precios'!$A$3:$K$2883,10,0),"") -> Futbol | AQ30: =IF($I30>0,VLOOKUP($I30,'Lista de Precios'!$A$3:$M$49893,13,0),"") -> Multideporte | XEO30: =+IF($AQ30=$XEO$13,$AM30,"") | XEP30: =+IF($AQ30=$XEP$13,$AM30,"") | XEQ30: =+IF($AQ30=$XEQ$13,$AM30,"") | XER30: =+IF($AQ30=$XER$13,$AM30,"")
A31: =IF($I31>0,VLOOKUP(I31,'Lista de Precios'!$A$3:$L$2883,9,0),0) -> 0 | B31: =IF($I31>0,VLOOKUP(I31,'Lista de Precios'!$A$3:$H$2883,7,0),0) -> 0 | C31: =IF($I31>0,VLOOKUP(I31,'Lista de Precios'!$A$3:$H$2883,2,0),"") | D31: =IF($I31>0,VLOOKUP(I31,'Lista de Precios'!$A$3:$H$2883,3,0),"") | E31: =IF($I31>0,VLOOKUP(I31,'Lista de Precios'!$A$3:$H$2883,6,0),"") | F31: =IF($I31>0,VLOOKUP(I31,'Lista de Precios'!$A$3:$H$2883,8,0),"") | G31: =IF(AN31="","",AN31*1.87) | H31: 0 | J31: =+E31 | AM31: =+IF(I31>0,SUM(L31:AL31),0) -> 0 | AN31: =+IF($I31>0,VLOOKUP($I31,'Lista de Precios'!$A$3:$H$2883,4,0),"") | AO31: =+IF(AM31>0,AN31*AM31,"") | AP31: =IF($I31>0,VLOOKUP($I31,'Lista de Precios'!$A$3:$K$2883,10,0),"") | AQ31: =IF($I31>0,VLOOKUP($I31,'Lista de Precios'!$A$3:$M$49893,13,0),"") | XEO31: =+IF($AQ31=$XEO$13,$AM31,"") | XEP31: =+IF($AQ31=$XEP$13,$AM31,"") | XEQ31: =+IF($AQ31=$XEQ$13,$AM31,"") | XER31: =+IF($AQ31=$XER$13,$AM31,"")
A32: =IF($I32>0,VLOOKUP(I32,'Lista de Precios'!$A$3:$L$2883,9,0),0) -> 0 | B32: =IF($I32>0,VLOOKUP(I32,'Lista de Precios'!$A$3:$H$2883,7,0),0) -> 0 | C32: =IF($I32>0,VLOOKUP(I32,'Lista de Precios'!$A$3:$H$2883,2,0),"") | D32: =IF($I32>0,VLOOKUP(I32,'Lista de Precios'!$A$3:$H$2883,3,0),"") | E32: =IF($I32>0,VLOOKUP(I32,'Lista de Precios'!$A$3:$H$2883,6,0),"") | F32: =IF($I32>0,VLOOKUP(I32,'Lista de Precios'!$A$3:$H$2883,8,0),"") | G32: =IF(AN32="","",AN32*1.87) | H32: 0 | J32: =+E32 | AM32: =+IF(I32>0,SUM(L32:AL32),0) -> 0 | AN32: =+IF($I32>0,VLOOKUP($I32,'Lista de Precios'!$A$3:$H$2883,4,0),"") | AO32: =+IF(AM32>0,AN32*AM32,"") | AP32: =IF($I32>0,VLOOKUP($I32,'Lista de Precios'!$A$3:$K$2883,10,0),"") | AQ32: =IF($I32>0,VLOOKUP($I32,'Lista de Precios'!$A$3:$M$49893,13,0),"") | XEO32: =+IF($AQ32=$XEO$13,$AM32,"") | XEP32: =+IF($AQ32=$XEP$13,$AM32,"") | XEQ32: =+IF($AQ32=$XEQ$13,$AM32,"") | XER32: =+IF($AQ32=$XER$13,$AM32,"")
A33: =IF($I33>0,VLOOKUP(I33,'Lista de Precios'!$A$3:$L$2883,9,0),0) -> 0 | B33: =IF($I33>0,VLOOKUP(I33,'Lista de Precios'!$A$3:$H$2883,7,0),0) -> 0 | C33: =IF($I33>0,VLOOKUP(I33,'Lista de Precios'!$A$3:$H$2883,2,0),"") | D33: =IF($I33>0,VLOOKUP(I33,'Lista de Precios'!$A$3:$H$2883,3,0),"") | E33: =IF($I33>0,VLOOKUP(I33,'Lista de Precios'!$A$3:$H$2883,6,0),"") | F33: =IF($I33>0,VLOOKUP(I33,'Lista de Precios'!$A$3:$H$2883,8,0),"") | G33: =IF(AN33="","",AN33*1.87) | H33: 0 | J33: =+E33 | AM33: =+IF(I33>0,SUM(L33:AL33),0) -> 0 | AN33: =+IF($I33>0,VLOOKUP($I33,'Lista de Precios'!$A$3:$H$2883,4,0),"") | AO33: =+IF(AM33>0,AN33*AM33,"") | AP33: =IF($I33>0,VLOOKUP($I33,'Lista de Precios'!$A$3:$K$2883,10,0),"") | AQ33: =IF($I33>0,VLOOKUP($I33,'Lista de Precios'!$A$3:$M$49893,13,0),"") | XEO33: =+IF($AQ33=$XEO$13,$AM33,"") | XEP33: =+IF($AQ33=$XEP$13,$AM33,"") | XEQ33: =+IF($AQ33=$XEQ$13,$AM33,"") | XER33: =+IF($AQ33=$XER$13,$AM33,"")
A34: =IF($I34>0,VLOOKUP(I34,'Lista de Precios'!$A$3:$L$2883,9,0),0) -> 0 | B34: =IF($I34>0,VLOOKUP(I34,'Lista de Precios'!$A$3:$H$2883,7,0),0) -> 0 | C34: =IF($I34>0,VLOOKUP(I34,'Lista de Precios'!$A$3:$H$2883,2,0),"") | D34: =IF($I34>0,VLOOKUP(I34,'Lista de Precios'!$A$3:$H$2883,3,0),"") | E34: =IF($I34>0,VLOOKUP(I34,'Lista de Precios'!$A$3:$H$2883,6,0),"") | F34: =IF($I34>0,VLOOKUP(I34,'Lista de Precios'!$A$3:$H$2883,8,0),"") | G34: =IF(AN34="","",AN34*1.87) | H34: 0 | J34: =+E34 | AM34: =+IF(I34>0,SUM(L34:AL34),0) -> 0 | AN34: =+IF($I34>0,VLOOKUP($I34,'Lista de Precios'!$A$3:$H$2883,4,0),"") | AO34: =+IF(AM34>0,AN34*AM34,"") | AP34: =IF($I34>0,VLOOKUP($I34,'Lista de Precios'!$A$3:$K$2883,10,0),"") | AQ34: =IF($I34>0,VLOOKUP($I34,'Lista de Precios'!$A$3:$M$49893,13,0),"") | XEO34: =+IF($AQ34=$XEO$13,$AM34,"") | XEP34: =+IF($AQ34=$XEP$13,$AM34,"") | XEQ34: =+IF($AQ34=$XEQ$13,$AM34,"") | XER34: =+IF($AQ34=$XER$13,$AM34,"")
A35: =IF($I35>0,VLOOKUP(I35,'Lista de Precios'!$A$3:$L$2883,9,0),0) -> 0 | B35: =IF($I35>0,VLOOKUP(I35,'Lista de Precios'!$A$3:$H$2883,7,0),0) -> 0 | C35: =IF($I35>0,VLOOKUP(I35,'Lista de Precios'!$A$3:$H$2883,2,0),"") | D35: =IF($I35>0,VLOOKUP(I35,'Lista de Precios'!$A$3:$H$2883,3,0),"") | E35: =IF($I35>0,VLOOKUP(I35,'Lista de Precios'!$A$3:$H$2883,6,0),"") | F35: =IF($I35>0,VLOOKUP(I35,'Lista de Precios'!$A$3:$H$2883,8,0),"") | G35: =IF(AN35="","",AN35*1.87) | H35: 0 | J35: =+E35 | AM35: =+IF(I35>0,SUM(L35:AL35),0) -> 0 | AN35: =+IF($I35>0,VLOOKUP($I35,'Lista de Precios'!$A$3:$H$2883,4,0),"") | AO35: =+IF(AM35>0,AN35*AM35,"") | AP35: =IF($I35>0,VLOOKUP($I35,'Lista de Precios'!$A$3:$K$2883,10,0),"") | AQ35: =IF($I35>0,VLOOKUP($I35,'Lista de Precios'!$A$3:$M$49893,13,0),"") | XEO35: =+IF($AQ35=$XEO$13,$AM35,"") | XEP35: =+IF($AQ35=$XEP$13,$AM35,"") | XEQ35: =+IF($AQ35=$XEQ$13,$AM35,"") | XER35: =+IF($AQ35=$XER$13,$AM35,"")
A36: =IF($I36>0,VLOOKUP(I36,'Lista de Precios'!$A$3:$L$2883,9,0),0) -> 0 | B36: =IF($I36>0,VLOOKUP(I36,'Lista de Precios'!$A$3:$H$2883,7,0),0) -> 0 | C36: =IF($I36>0,VLOOKUP(I36,'Lista de Precios'!$A$3:$H$2883,2,0),"") | D36: =IF($I36>0,VLOOKUP(I36,'Lista de Precios'!$A$3:$H$2883,3,0),"") | E36: =IF($I36>0,VLOOKUP(I36,'Lista de Precios'!$A$3:$H$2883,6,0),"") | F36: =IF($I36>0,VLOOKUP(I36,'Lista de Precios'!$A$3:$H$2883,8,0),"") | G36: =IF(AN36="","",AN36*1.87) | H36: 0 | J36: =+E36 | AM36: =+IF(I36>0,SUM(L36:AL36),0) -> 0 | AN36: =+IF($I36>0,VLOOKUP($I36,'Lista de Precios'!$A$3:$H$2883,4,0),"") | AO36: =+IF(AM36>0,AN36*AM36,"") | AP36: =IF($I36>0,VLOOKUP($I36,'Lista de Precios'!$A$3:$K$2883,10,0),"") | AQ36: =IF($I36>0,VLOOKUP($I36,'Lista de Precios'!$A$3:$M$49893,13,0),"") | XEO36: =+IF($AQ36=$XEO$13,$AM36,"") | XEP36: =+IF($AQ36=$XEP$13,$AM36,"") | XEQ36: =+IF($AQ36=$XEQ$13,$AM36,"") | XER36: =+IF($AQ36=$XER$13,$AM36,"")
A37: =IF($I37>0,VLOOKUP(I37,'Lista de Precios'!$A$3:$L$2883,9,0),0) -> 0 | B37: =IF($I37>0,VLOOKUP(I37,'Lista de Precios'!$A$3:$H$2883,7,0),0) -> 0 | C37: =IF($I37>0,VLOOKUP(I37,'Lista de Precios'!$A$3:$H$2883,2,0),"") | D37: =IF($I37>0,VLOOKUP(I37,'Lista de Precios'!$A$3:$H$2883,3,0),"") | E37: =IF($I37>0,VLOOKUP(I37,'Lista de Precios'!$A$3:$H$2883,6,0),"") | F37: =IF($I37>0,VLOOKUP(I37,'Lista de Precios'!$A$3:$H$2883,8,0),"") | G37: =IF(AN37="","",AN37*1.87) | H37: 0 | J37: =+E37 | AM37: =+IF(I37>0,SUM(L37:AL37),0) -> 0 | AN37: =+IF($I37>0,VLOOKUP($I37,'Lista de Precios'!$A$3:$H$2883,4,0),"") | AO37: =+IF(AM37>0,AN37*AM37,"") | AP37: =IF($I37>0,VLOOKUP($I37,'Lista de Precios'!$A$3:$K$2883,10,0),"") | AQ37: =IF($I37>0,VLOOKUP($I37,'Lista de Precios'!$A$3:$M$49893,13,0),"") | XEO37: =+IF($AQ37=$XEO$13,$AM37,"") | XEP37: =+IF($AQ37=$XEP$13,$AM37,"") | XEQ37: =+IF($AQ37=$XEQ$13,$AM37,"") | XER37: =+IF($AQ37=$XER$13,$AM37,"")
A38: =IF($I38>0,VLOOKUP(I38,'Lista de Precios'!$A$3:$L$2883,9,0),0) -> 0 | B38: =IF($I38>0,VLOOKUP(I38,'Lista de Precios'!$A$3:$H$2883,7,0),0) -> 0 | C38: =IF($I38>0,VLOOKUP(I38,'Lista de Precios'!$A$3:$H$2883,2,0),"") | D38: =IF($I38>0,VLOOKUP(I38,'Lista de Precios'!$A$3:$H$2883,3,0),"") | E38: =IF($I38>0,VLOOKUP(I38,'Lista de Precios'!$A$3:$H$2883,6,0),"") | F38: =IF($I38>0,VLOOKUP(I38,'Lista de Precios'!$A$3:$H$2883,8,0),"") | G38: =IF(AN38="","",AN38*1.87) | H38: 0 | J38: =+E38 | AM38: =+IF(I38>0,SUM(L38:AL38),0) -> 0 | AN38: =+IF($I38>0,VLOOKUP($I38,'Lista de Precios'!$A$3:$H$2883,4,0),"") | AO38: =+IF(AM38>0,AN38*AM38,"") | AP38: =IF($I38>0,VLOOKUP($I38,'Lista de Precios'!$A$3:$K$2883,10,0),"") | AQ38: =IF($I38>0,VLOOKUP($I38,'Lista de Precios'!$A$3:$M$49893,13,0),"") | XEO38: =+IF($AQ38=$XEO$13,$AM38,"") | XEP38: =+IF($AQ38=$XEP$13,$AM38,"") | XEQ38: =+IF($AQ38=$XEQ$13,$AM38,"") | XER38: =+IF($AQ38=$XER$13,$AM38,"")
